Workbook

Sheet AMB-Index
A1: Ambuja Cements Ltd: Business Analysis and Valuation
A2: CONSOLIDATED basis. Rs crore unless stated. FYE 31 March. Valuation date 31 March 2026.
A4: No. | B4: Sheet | C4: What it contains
A5: 1 | B5: Source-Log | C5: Every input traced to its publisher. Open items and re-source flags in red.
A6: 2 | B6: Source-Data | C6: FY2024-25 and FY2025-26 consolidated actuals, exactly as reported, plus derived ratios.
A7: 3 | B7: Assumptions | C7: All drivers in one place. Blue on yellow means edit here.
A8: 4 | B8: PnL-Forecast | C8: Ten year forecast built on capacity times utilisation and EBITDA per tonne.
A9: 5 | B9: Invested-Capital | C9: Invested capital roll forward separating goodwill from operating capital, and the ROIC path.
A10: 6 | B10: Cost-of-Capital | C10: Risk free, ERP, bottom up beta, WACC and the unlevered rate rho.
A11: 7 | B11: FCFF | C11: Enterprise DCF at WACC.
A12: 8 | B12: CCF | C12: Capital cash flow at rho.
A13: 9 | B13: APV | C13: Unlevered value plus the tax shield.
A14: 10 | B14: FCFE | C14: Equity DCF at the cost of equity.
A15: 11 | B15: EVA | C15: Opening invested capital plus the present value of future EVA.
A16: 12 | B16: Reconciliation | C16: Proof the five methods agree.
... A19: 15 | B19: Summary | C19: Valuation summary, the merger adjustment, and the conclusion.
A21: Why this model differs from the UltraTech model
B22: CONSOLIDATED, not standalone. Ambuja standalone is roughly 60% of the group and excludes ACC entirely, so dividing a group market capitalisation by standalone EBITDA overstates the multiple badly. Ambuja is also merging ACC, Orient, Sanghi and Penna into itself, after which one consolidated entity is the only sensible unit.
B23: TEN year explicit forecast, not five. Ambuja runs at about 68% capacity utilisation against UltraTech's 82%, and its return on capital is far below its cost of capital today. A five year window ends before the ramp has played out and throws almost the entire value into the terminal period. The course treats a longer explicit period as the standard answer for a difficult to value company.
B24: GOODWILL is separated from operating invested capital. Acquisitions left Rs 22,979 crore of goodwill and intangibles on the balance sheet. It belongs in invested capital when measuring the return shareholders earn on what they paid, but it must NOT be grown at g in the terminal reinvestment, because organic growth does not require buying more goodwill. Getting this wrong understated the value by about Rs 46 per share.
B25: NON-CONTROLLING INTEREST of Rs 12,499 crore is deducted in the bridge, because consolidated cash flows include 100% of subsidiaries the parent does not wholly own. Post merger this reverses and the share count rises 13.7% instead. Both routes are shown on the Summary sheet and should give a similar answer.
B26: KNOWN INCONSISTENCY WITH THE ULTRATECH MODEL, stated openly. UltraTech holds 74.99% of the listed India Cements and is valued STANDALONE with that stake added at book. Ambuja holds 50.05% of the listed ACC and is valued CONSOLIDATED. Two companies in the same structural position are treated two different ways, and the reason is data availability rather than principle: UltraTech publishes a ten year standalone history and no comparable consolidated one, while Ambuja's consolidated statements were available and its standalone accounts exclude more than a third of the business. The irony is that UltraTech's stake is the MORE controlling of the two. Before submission, either consolidate both or value both by sum of parts. Until then this is a disclosed weakness, not a hidden one.
A28: Read before using any number
B29: The Indian 10 year G-Sec yield is still a PLACEHOLDER at 6.50% and must come from RBI or FBIL.
B30: Consolidated history is only two years deep here, FY2024-25 restated and FY2025-26, because that is what the annual report provides. Earlier consolidated years exist only in broker research, which is not an authorised source. The ROIC trend is therefore asserted from two points, which is thin. Say so in the report.
B31: Ambuja's reported tax line is a CREDIT, so reported PAT exceeds PBT. All returns here are computed at the statutory rate of 25.168%, never at the reported effective rate of minus 71%.

Sheet AMB-Audit Log
A1: Source Log
A3: # | B3: Item | C3: Publisher | D3: Source and location | E3: Accessed | F3: Period | G3: Feeds
A4: 1 | B4: Consolidated Statement of Profit and Loss | C4: Ambuja Cements Ltd | D4: Integrated Annual Report 2025-26, consolidated P&L | E4: 2026-08-26 | F4: FY26 and FY25 restated | G4: Source-Data
A5: 2 | B5: Consolidated Balance Sheet | C5: Ambuja Cements Ltd | D5: Same report, consolidated balance sheet | E5: 2026-08-26 | F5: 31-Mar-2026 | G5: Source-Data, Assumptions
A6: 3 | B6: Consolidated highlights: volume | C6: Ambuja Cements Ltd | D6: Same report, Growth Trajectory: cement sales volume 74 million tonnes, revenue Rs 40,656 cr | E6: 2026-08-26 | F6: FY2025-26 | G6: Assumptions, opening position
A7: 4 | B7: Capacity 109 MTPA, target 119 MTPA | C7: Ambuja Cements Ltd | D7: Same report: current capacity of 109 MTPA and a targeted capacity of 119 MTPA | E7: 2026-08-26 | F7: FY2025-26 | G7: Assumptions, capacity
A8: 5 | B8: Market capitalisation Rs 99,095 cr | C8: Ambuja Cements Ltd | D8: Same report, highlights, as at 31 March 2026 (last traded 30 March) | E8: 2026-08-26 | F8: 30-Mar-2026 | G8: Assumptions
A9: 6 | B9: Holding in ACC 50.05% | C9: Ambuja Cements Ltd | D9: Same report, subsidiary listing | E9: 2026-08-26 | F9: 31-Mar-2026 | G9: Merger note
A10: 7 | B10: Tax note 32(ii) | C10: Ambuja Cements Ltd | D10: Rs 1,179.71 cr of earlier year provisions released on favourable High Court decisions, plus Rs 71.05 cr revision of the FY25 provision | E10: 2026-08-26 | F10: FY2025-26 | G10: Tax normalisation
A11: 8 | B11: India ERP 7.08%, default spread 1.87% | C11: Damodaran, NYU Stern | D11: Country Default Spreads and Risk Premiums, January 2026 | E11: 2026-08-26 | F11: Jan-2026 | G11: Cost-of-Capital
A12: 9 | B12: Unlevered beta 0.90 | C12: Damodaran, NYU Stern | D12: Betas by Sector (Global), January 2026, Building Materials, corrected for cash | E12: 2026-08-26 | F12: Jan-2026 | G12: Cost-of-Capital
A13: 10 | B13: ASSUMPTION: tax 25.168% | C13: Own assumption | D13: Section 115BAA. Used because the reported effective rate is negative and unusable. | E13: 2026-08-26 | F13: FY2025-26 | G13: Throughout
A14: 11 | B14: 10 year G-Sec par yield 6.85% | C14: RBI / FBIL | D14: Ratios and Rates release dated 27-Mar-2026: 10-Year G-Sec Par Yield (FBIL), week ended 20-Mar-2026. Last weekly print before the valuation date, so it matches the market and balance sheet dates exactly. | E14: 2026-08-27 | F14: Week ended 20-Mar-2026 | G14: Cost-of-Capital
A15: 12 | B15: RE-SOURCE: merger terms and dilution | C15: Ambuja filings | D15: Swap ratios of 325 Ambuja per 100 ACC and 33 per 100 Orient, 13.7% dilution, promoter holding 67.65% to 60.94%. These reached the model through BROKER research, which is not an authorised source. Re-source from the scheme filing. | E15: 2026-08-26 | F15: Dec-2025 | G15: Summary, merger note
A16: 13 | B16: NOT USED: broker forecasts | C16: HDFC Securities | D16: Their December 2025 FY26E EBITDA of Rs 8,477 cr came in at Rs 6,539 cr actual, a 30% miss, on a revenue estimate that was accurate to 2.7%. Facts used, forecasts rejected. | E16: 2026-08-26 | F16: Dec-2025 | G16: Sensitivity, commentary
A18: No data in this workbook comes from moneycontrol, screener.in, Yahoo Finance or any other aggregator.
A21: MODEL AUDIT LOG: issues found during the build, and what was done about them
A22: # | B22: Where | C22: Severity | D22: Finding | E22: Valuation impact | F22: Fix applied
A23: 1 | B23: Balance Sheet, depreciation | C23: HIGH | D23: Depreciation is charged at 8.0% of OPERATING fixed assets, but the historical charge includes amortisation of the Rs 9,433 cr intangible balance, which the model holds flat and never amortises. Charge and base do not match. | E23: Small but the inconsistency is real | F23: DOCUMENTED, NOT FIXED. Splitting the charge into PPE depreciation and intangible amortisation requires a disclosed split of the two in the notes, which was not obtained. Flagged as a PARTIAL on the Dashboard.
A24: 2 | B24: Relative Valuation, peer basis | C24: MED | D24: Ambuja is carried CONSOLIDATED and every peer STANDALONE, so the multiples are not strictly comparable. | E24: Ambuja's EV/EBITDA would print 34x on the wrong pairing against 17.0x on the right one | F24: FIXED AND DISCLOSED. Non-controlling interest is added to enterprise value and a basis row labels every company. For the other four companies standalone and consolidated differ by under 10%, so the mismatch does not arise.
A25: 3 | B25: Terminal, ROIC spread | C25: MED | D25: Terminal ROIC needed to be shown against WACC to satisfy Golden Check 6. | E25: None; the check passes | F25: FIXED. Terminal ROIC of 11.9% against a WACC of 11.375% is a spread of 0.55 points, documented on the Terminal sheet and the Dashboard.
A26: 4 | B26: Model build, goodwill in terminal | C26: HIGH | D26: Terminal reinvestment was charged on invested capital INCLUDING goodwill, which assumes the company must keep buying goodwill forever merely to grow. | E26: Drove the equity value NEGATIVE | F26: FIXED. Terminal reinvestment is charged on OPERATING invested capital only. Worth about Rs 46 per share.
A27: 5 | B27: Model build, forecast horizon | C27: HIGH | D27: A five year explicit horizon ended before the utilisation ramp had played out. | E27: Understated value by roughly Rs 83 per share | F27: FIXED. Extended to a ten year explicit forecast, which is the standard treatment for a difficult to value company.
A28: 6 | B28: Assumptions, terminal growth | C28: HIGH | D28: Terminal growth was originally set LOWER than UltraTech's on the reasoning that a company earning below its cost of capital is worth more if it grows less. That reasoning was result driven AND factually backwards. | E28: Material | F28: FIXED. Both companies now use the same fraction of nominal GDP. Terminal growth is 6.99%, being 65% of nominal GDP of 10.76%.
A29: 7 | B29: Tax normalisation | C29: HIGH | D29: The reported tax line is a net CREDIT of Rs 2,338 cr, so reported profit exceeds pre-tax profit and the effective rate is minus 71%. | E29: Would overstate every return measure | F29: FIXED. All returns are computed at the statutory 25.168%. The credit is decomposed into three drivers on the Normalize sheet, net effect minus Rs 11.54 per share.
A31: Every entry above was found by us during the build, not by a reviewer afterwards. Where an item is marked PARTIALLY FIXED or DOCUMENTED NOT FIXED, the reason is stated and the direction of the residual error is given. Three of the fixes moved the valuation AGAINST our own recommendation, which is recorded deliberately.
A34: MODEL AUDIT LOG: issues found during the build, and what was done about them
A35: # | B35: Where | C35: Severity | D35: Finding | E35: Valuation impact | F35: Fix applied
A36: 1 | B36: Balance Sheet, depreciation | C36: HIGH | D36: Depreciation is charged at 8.0% of OPERATING fixed assets, but the historical charge includes amortisation of the Rs 9,433 cr intangible balance, which the model holds flat and never amortises. Charge and base do not match. | E36: Small but the inconsistency is real | F36: DOCUMENTED, NOT FIXED. Splitting the charge into PPE depreciation and intangible amortisation requires a disclosed split of the two in the notes, which was not obtained. Flagged as a PARTIAL on the Dashboard.
A37: 2 | B37: Relative Valuation, peer basis | C37: MED | D37: Ambuja is carried CONSOLIDATED and every peer STANDALONE, so the multiples are not strictly comparable. | E37: Ambuja's EV/EBITDA would print 34x on the wrong pairing against 17.0x on the right one | F37: FIXED AND DISCLOSED. Non-controlling interest is added to enterprise value and a basis row labels every company. For the other four companies standalone and consolidated differ by under 10%, so the mismatch does not arise.
A38: 3 | B38: Terminal, ROIC spread | C38: MED | D38: Terminal ROIC needed to be shown against WACC to satisfy Golden Check 6. | E38: None; the check passes | F38: FIXED. Terminal ROIC of 11.9% against a WACC of 11.375% is a spread of 0.55 points, documented on the Terminal sheet and the Dashboard.
A39: 4 | B39: Model build, goodwill in terminal | C39: HIGH | D39: Terminal reinvestment was charged on invested capital INCLUDING goodwill, which assumes the company must keep buying goodwill forever merely to grow. | E39: Drove the equity value NEGATIVE | F39: FIXED. Terminal reinvestment is charged on OPERATING invested capital only. Worth about Rs 46 per share.
A40: 5 | B40: Model build, forecast horizon | C40: HIGH | D40: A five year explicit horizon ended before the utilisation ramp had played out. | E40: Understated value by roughly Rs 83 per share | F40: FIXED. Extended to a ten year explicit forecast, which is the standard treatment for a difficult to value company.
A41: 6 | B41: Assumptions, terminal growth | C41: HIGH | D41: Terminal growth was originally set LOWER than UltraTech's on the reasoning that a company earning below its cost of capital is worth more if it grows less. That reasoning was result driven AND factually backwards. | E41: Material | F41: FIXED. Both companies now use the same fraction of nominal GDP. Terminal growth is 6.99%, being 65% of nominal GDP of 10.76%.
A42: 7 | B42: Tax normalisation | C42: HIGH | D42: The reported tax line is a net CREDIT of Rs 2,338 cr, so reported profit exceeds pre-tax profit and the effective rate is minus 71%. | E42: Would overstate every return measure | F42: FIXED. All returns are computed at the statutory 25.168%. The credit is decomposed into three drivers on the Normalize sheet, net effect minus Rs 11.54 per share.
A44: Every entry above was found by us during the build, not by a reviewer afterwards. Where an item is marked PARTIALLY FIXED or DOCUMENTED NOT FIXED, the reason is stated and the direction of the residual error is given. Three of the fixes moved the valuation AGAINST our own recommendation, which is recorded deliberately.
A47: MODEL AUDIT LOG: issues found during the build, and what was done about them
A48: # | B48: Where | C48: Severity | D48: Finding | E48: Valuation impact | F48: Fix applied
A49: 1 | B49: Balance Sheet, depreciation | C49: HIGH | D49: Depreciation is charged at 8.0% of OPERATING fixed assets, but the historical charge includes amortisation of the Rs 9,433 cr intangible balance, which the model holds flat and never amortises. Charge and base do not match. | E49: Small but the inconsistency is real | F49: DOCUMENTED, NOT FIXED. Splitting the charge into PPE depreciation and intangible amortisation requires a disclosed split of the two in the notes, which was not obtained. Flagged as a PARTIAL on the Dashboard.
A50: 2 | B50: Relative Valuation, peer basis | C50: MED | D50: Ambuja is carried CONSOLIDATED and every peer STANDALONE, so the multiples are not strictly comparable. | E50: Ambuja's EV/EBITDA would print 34x on the wrong pairing against 17.0x on the right one | F50: FIXED AND DISCLOSED. Non-controlling interest is added to enterprise value and a basis row labels every company. For the other four companies standalone and consolidated differ by under 10%, so the mismatch does not arise.
...

Sheet AMB-Source Data
A1: Line item (consolidated, as reported) | B1: Unit | C1: FY2025-26 | D1: FY2024-25 restated
A2: Revenue from operations | B2: Rs cr | C2: 40446.04 | D2: 33989.38
A3: Government grants including duty credits | B3: Rs cr | C3: 209.64 | D3: 1347.06
A4: Other income | B4: Rs cr | C4: 834.34 | D4: 2654.25
A5: Total income | B5: Rs cr | C5: 41490.02 | D5: 37990.69
A6: Finance costs | B6: Rs cr | C6: 223.61 | D6: 215.94
A7: Depreciation and amortisation | B7: Rs cr | C7: 3570.41 | D7: 2297.04
A8: Profit before exceptional items and tax | B8: Rs cr | C8: 3599.31 | D8: 6125.14
A9: Exceptional items, expense | B9: Rs cr | C9: 300.54 | D9: 21.47
A10: Profit before tax | B10: Rs cr | C10: 3298.77 | D10: 6103.67
A11: Profit for the year, owners of the parent | B11: Rs cr | C11: 4728.18 | D11: 4303.1
A12: Profit for the year, non-controlling interest | B12: Rs cr | C12: 908.9 | D12: 990.98
A13: Cement sales volume | B13: mn T | C13: 74
A14: Property, plant and equipment | B14: Rs cr | C14: 33801.18 | D14: 25049.28
A15: Right-of-use assets | B15: Rs cr | C15: 1483 | D15: 1464.76
A16: Capital work in progress | B16: Rs cr | C16: 9084.7 | D16: 9792.99
A17: Goodwill | B17: Rs cr | C17: 13545.52 | D17: 10942.83
A18: Other intangible assets | B18: Rs cr | C18: 9433.12 | D18: 5309.24
A19: Equity attributable to owners | B19: Rs cr | C19: 59347.32 | D19: 53578.92
A20: Non-controlling interest | B20: Rs cr | C20: 12498.92 | D20: 10368.17
A21: Borrowings, non-current | B21: Rs cr | C21: 44.79 | D21: 14.39
A22: Borrowings, current | B22: Rs cr | C22: 7.99 | D22: 12.43
A23: Lease liabilities, total | B23: Rs cr | C23: 813.15 | D23: 761.68
A24: Cash and cash equivalents | B24: Rs cr | C24: 891.59 | D24: 5043.32
A25: Bank balances other than above | B25: Rs cr | C25: 67.01 | D25: 1128.84
... A27: Deferred tax liabilities (net) | B27: Rs cr | C27: 3466.33 | D27: 2432.85
A29: Derived
A30: Revenue including government grants | C30: =C2+C3 -> 40655.68 | D30: =D2+D3 -> 35336.44
A31: EBITDA (uniform definition) | C31: =C8+C6+C7-C4 -> 6558.99 | D31: =D8+D6+D7-D4 -> 5983.87
A32: EBIT | C32: =C29-C7 -> -3570.41
A33: Reported profit for the year | C33: =C11+C12 -> 5637.08 | D33: =D11+D12 -> 5294.08
A34: Reported effective tax rate | C34: =(C10-C29)/C10 -> 1
A35: Operating invested capital (PPE, ROU, CWIP, NWC) | C35: =C14+C15+C16+'AMB-Assumptions'!$B$4 -> 44368.88
A36: Goodwill and other intangibles | C36: =C17+C18 -> 22978.64 | D36: =D17+D18 -> 16252.07
A37: Net debt (borrowings + leases - cash) | C37: =C21+C22+C23-C24-C25-C26 -> -92.67 | D37: =D21+D22+D23-D24-D25-D26 -> -7205.82
A39: The uniform EBITDA definition gives Rs 6,559 crore for FY2025-26. The company's own Operating EBITDA line reads Rs 6,539 crore; the Rs 20 crore difference is the share of profit of joint ventures and associates, which sits outside this definition. Ties to within 0.3%, which is the check that the definition is right.

Sheet AMB-Entity Build
A1: Entity Build: standalone to consolidated
A2: Ambuja Cements Ltd, FY2025-26. Standalone and consolidated are as reported; the subsidiary column is derived as the difference.
A4: Line item | B4: Unit | C4: Standalone | D4: Subsidiaries | E4: Consolidated | F4: Check
A5: Revenue from operations | B5: Rs cr | C5: 25052.05 | D5: =E5-C5 -> 15393.99 | E5: 40446.04
A6: Government grants | B6: Rs cr | C6: 9.49 | D6: =E6-C6 -> 200.15 | E6: 209.64
A7: Other income | B7: Rs cr | C7: 766.17 | D7: =E7-C7 -> 68.17 | E7: 834.34
A8: Finance costs | B8: Rs cr | C8: 172.56 | D8: =E8-C8 -> 51.05 | E8: 223.61
A9: Depreciation and amortisation | B9: Rs cr | C9: 2035.2 | D9: =E9-C9 -> 1535.21 | E9: 3570.41
A10: Profit before exceptional items and tax | B10: Rs cr | C10: 1488.25 | D10: =E10-C10 -> 2111.06 | E10: 3599.31
A11: Revenue including grants | C11: =C5+C6 -> 25061.54 | D11: =D5+D6 -> 15594.14 | E11: =E5+E6 -> 40655.68
A12: EBITDA (uniform definition) | C12: =C10+C8+C9-C7 -> 2929.84 | D12: =D10+D8+D9-D7 -> 3629.15 | E12: =E10+E8+E9-E7 -> 6558.99
A13: EBITDA margin | C13: =C12/C11 -> 0.11690582 | D13: =D12/D11 -> 0.23272524 | E13: =E12/E11 -> 0.16133022
A14: Share of group revenue | C14: =C11/$E$11 -> 0.61643392 | D14: =D11/$E$11 -> 0.38356608
A15: Share of group EBITDA | C15: =C12/$E$12 -> 0.44669073 | D15: =D12/$E$12 -> 0.55330927
A17: THE FINDING. Ambuja standalone carries 61.6% of group revenue but only 44.7% of group EBITDA. The parent runs an 11.7% margin while the subsidiaries run 23.3%. The weak assets, principally Sanghi and Penna, sit inside the standalone entity, while ACC and Orient sit outside it. A consolidated-only model hides this entirely, which is why this tab exists and why the valuation is presented as a build up.
A21: Why the forecast is nonetheless run at consolidated level
A22: Volume of 74 million tonnes and capacity of 109 MTPA are disclosed CONSOLIDATED ONLY. Splitting them by revenue share would imply standalone volume of about 45.6 million tonnes, but that is a derivation and not a disclosure, and forecasting a derived volume series against a disclosed capacity series would be false precision. The base year build above is fully sourced; the forecast therefore runs on consolidated capacity times utilisation times EBITDA per tonne, and the equity bridge deducts the non-controlling interest so that only the owners' share is valued. If standalone volume is obtained from the company, this tab is where a two block forecast would be built.
A28: Basis decision and its consequence for the multiple
A29: Basis | C29: EBITDA | D29: Enterprise value | E29: EV/EBITDA
A30: Standalone (wrong pairing) | C30: 2929.84 | D30: 99675.72 | E30: =D30/C30 -> 34.020875
A31: Consolidated with NCI added | C31: 6558.99 | D31: 111501.25 | E31: =D31/C31 -> 16.999759
A33: Market capitalisation of Rs 99,095 crore prices the whole group including the 50.05% stake in ACC. Dividing it by standalone EBITDA prints 34x and is a category error. Adding the non-controlling interest of Rs 12,499 crore to enterprise value and dividing by consolidated EBITDA gives 17.0x. This is the pairing used throughout the model and in the peer comparison.
A36: CONSISTENCY CHECK: the build must tie to the reported total
A37: Revenue: standalone plus subsidiaries | C37: =C11+D11 -> 40655.68 | D37: =E11 -> 40655.68 | E37: =IF(ABS(C37-D37)<0.01,"TIES","DOES NOT TIE") -> TIES
A38: EBITDA: standalone plus subsidiaries | C38: =C12+D12 -> 6558.99 | D38: =E12 -> 6558.99 | E38: =IF(ABS(C38-D38)<0.01,"TIES","DOES NOT TIE") -> TIES
C39: Build | D39: As reported | E39: Check
A41: This is the MRF style tie out. The two blocks are not independent estimates that happen to be near the total; the subsidiary column is DERIVED as consolidated less standalone, so it ties by construction and the check confirms no transcription error. In the forecast the same discipline holds: consolidated revenue is built from capacity and then SPLIT, so the blocks always sum to the total. Note the residual caveat: intercompany eliminations sit inside the subsidiary column because they cannot be separated from the published statements.
A44: CONSISTENCY CHECK: the build must tie to the reported total
A45: Revenue: standalone plus subsidiaries | C45: =C11+D11 -> 40655.68 | D45: =E11 -> 40655.68 | E45: =IF(ABS(C45-D45)<0.01,"TIES","DOES NOT TIE") -> TIES
A46: EBITDA: standalone plus subsidiaries | C46: =C12+D12 -> 6558.99 | D46: =E12 -> 6558.99 | E46: =IF(ABS(C46-D46)<0.01,"TIES","DOES NOT TIE") -> TIES
C47: Build | D47: As reported | E47: Check
A49: This is the MRF style tie out. The two blocks are not independent estimates that happen to be near the total; the subsidiary column is DERIVED as consolidated less standalone, so it ties by construction and the check confirms no transcription error. In the forecast the same discipline holds: consolidated revenue is built from capacity and then SPLIT, so the blocks always sum to the total. Note the residual caveat: intercompany eliminations sit inside the subsidiary column because they cannot be separated from the published statements.
A52: CONSISTENCY CHECK: the build must tie to the reported total
A53: Revenue: standalone plus subsidiaries | C53: =C11+D11 -> 40655.68 | D53: =E11 -> 40655.68 | E53: =IF(ABS(C53-D53)<0.01,"TIES","DOES NOT TIE") -> TIES
A54: EBITDA: standalone plus subsidiaries | C54: =C12+D12 -> 6558.99 | D54: =E12 -> 6558.99 | E54: =IF(ABS(C54-D54)<0.01,"TIES","DOES NOT TIE") -> TIES
C55: Build | D55: As reported | E55: Check
A57: This is the MRF style tie out. The two blocks are not independent estimates that happen to be near the total; the subsidiary column is DERIVED as consolidated less standalone, so it ties by construction and the check confirms no transcription error. In the forecast the same discipline holds: consolidated revenue is built from capacity and then SPLIT, so the blocks always sum to the total. Note the residual caveat: intercompany eliminations sit inside the subsidiary column because they cannot be separated from the published statements.
A60: CONSISTENCY CHECK: the build must tie to the reported total
A61: Revenue: standalone plus subsidiaries | C61: =C11+D11 -> 40655.68 | D61: =E11 -> 40655.68 | E61: =IF(ABS(C61-D61)<0.01,"TIES","DOES NOT TIE") -> TIES
A62: EBITDA: standalone plus subsidiaries | C62: =C12+D12 -> 6558.99 | D62: =E12 -> 6558.99 | E62: =IF(ABS(C62-D62)<0.01,"TIES","DOES NOT TIE") -> TIES
...

Sheet AMB-Normalize
A1: Normalisation and reclassification
A2: Every adjustment carries the annual report note reference it came from.
A4: Item | B4: Unit | C4: As reported | D4: Normalised | E4: Basis and note reference
A5: Tax expense (credit), consolidated | B5: Rs cr | C5: -2338.31 | D5: 830.28 | E5: Note 32. Reported line is a net CREDIT of Rs 2,338.31 cr, giving an effective rate of minus 70.9%. Replaced throughout by the statutory rate of 25.168% under s.115BAA applied to EBIT.
A6: Driver 1: litigation provisions released | B6: Rs cr | C6: 1250.76 | D6: 0 | E6: Note 32(ii). Rs 1,179.71 cr of earlier year provisions released on favourable High Court decisions, plus Rs 71.05 cr revising FY2024-25. Non cash, prior period. Excluded.
A7: Driver 1a: duty and taxes paid under protest | B7: Rs cr | C7: 614.1 | D7: 614.1 | E7: Note 53, non-current. Real cash already paid, recoverable on favourable rulings. Sits outside operating invested capital. ADDED as a non-operating asset.
A8: Driver 2: deferred tax liabilities (net) | B8: Rs cr | C8: 3466.33 | D8: 3466.33 | E8: Balance sheet. Treated as a real liability and DEDUCTED in the equity bridge as a one time drop, not amortised.
A9: Driver 3: DTA on losses and unabsorbed depreciation | B9: Rs cr | C9: 345.78 | D9: 0 | E9: Note 32. Memo only. Already netted inside Driver 2, so adding it again would double count. Note it is SHRINKING: Rs 509.66 cr opening, Rs 163.88 cr consumed, Rs 345.78 cr closing.
A10: Exceptional items, consolidated | B10: Rs cr | C10: 300.54 | D10: 0 | E10: Consolidated P&L. Removed from earnings; sits below profit before exceptional items so EBITDA needs no adjustment.
A11: Non-controlling interest | B11: Rs cr | C11: 12498.92 | D11: 12498.92 | E11: Balance sheet. DEDUCTED in the bridge because consolidated cash flows include 100% of partly owned subsidiaries.
A12: Other income | B12: Rs cr | C12: 834.34 | D12: 0 | E12: Excluded from EBITDA under our uniform definition, so cash and investments are non-operating and added back once at the bridge.
A14: Net effect of the three tax drivers on value: minus Rs 11.54 per share. The headline credit of Rs 2,338 crore, which lifts reported profit 71% above pre-tax profit, is worth negative value once each component is treated on its economics rather than its accounting.

Sheet AMB-Common Size
A1: Common Size Statements: Ambuja Cements (consolidated)
A2: Recomputed from the consolidated statements on Source-Data. Nothing downloaded.
A4: Line item | B4: FY2025-26 | C4: FY2024-25 restated
A5: Income statement, percent of revenue including government grants
A6: Other income | B6: ='AMB-Source Data'!C4/('AMB-Source Data'!C2+'AMB-Source Data'!C3) -> 0.020522102 | C6: ='AMB-Source Data'!D4/('AMB-Source Data'!D2+'AMB-Source Data'!D3) -> 0.075113679
A7: EBITDA (uniform definition) | B7: =('AMB-Source Data'!C8+'AMB-Source Data'!C6+'AMB-Source Data'!C7-'AMB-Source Data'!C4)/('AMB-Source Data'!C2+'AMB-Source Data'!C3) -> 0.16133022 | C7: =('AMB-Source Data'!D8+'AMB-Source Data'!D6+'AMB-Source Data'!D7-'AMB-Source Data'!D4)/('AMB-Source Data'!D2+'AMB-Source Data'!D3) -> 0.16933992
A8: Depreciation and amortisation | B8: ='AMB-Source Data'!C7/('AMB-Source Data'!C2+'AMB-Source Data'!C3) -> 0.087820693 | C8: ='AMB-Source Data'!D7/('AMB-Source Data'!D2+'AMB-Source Data'!D3) -> 0.065004851
A9: Finance costs | B9: ='AMB-Source Data'!C6/('AMB-Source Data'!C2+'AMB-Source Data'!C3) -> 0.0055000925 | C9: ='AMB-Source Data'!D6/('AMB-Source Data'!D2+'AMB-Source Data'!D3) -> 0.0061109721
A10: Profit before exceptional items and tax | B10: ='AMB-Source Data'!C8/('AMB-Source Data'!C2+'AMB-Source Data'!C3) -> 0.088531541 | C10: ='AMB-Source Data'!D8/('AMB-Source Data'!D2+'AMB-Source Data'!D3) -> 0.17333778
A11: Exceptional items | B11: ='AMB-Source Data'!C9/('AMB-Source Data'!C2+'AMB-Source Data'!C3) -> 0.007392325 | C11: ='AMB-Source Data'!D9/('AMB-Source Data'!D2+'AMB-Source Data'!D3) -> 0.00060758809
A12: Profit for the year (total) | B12: =('AMB-Source Data'!C11+'AMB-Source Data'!C12)/('AMB-Source Data'!C2+'AMB-Source Data'!C3) -> 0.13865418 | C12: =('AMB-Source Data'!D11+'AMB-Source Data'!D12)/('AMB-Source Data'!D2+'AMB-Source Data'!D3) -> 0.14981928
A13: Profit attributable to owners | B13: ='AMB-Source Data'!C11/('AMB-Source Data'!C2+'AMB-Source Data'!C3) -> 0.11629814 | C13: ='AMB-Source Data'!D11/('AMB-Source Data'!D2+'AMB-Source Data'!D3) -> 0.12177514
A14: Profit attributable to minorities | B14: ='AMB-Source Data'!C12/('AMB-Source Data'!C2+'AMB-Source Data'!C3) -> 0.02235604 | C14: ='AMB-Source Data'!D12/('AMB-Source Data'!D2+'AMB-Source Data'!D3) -> 0.028044138
A16: Capital employed, percent of total
A17: Property, plant and equipment | B17: ='AMB-Source Data'!C14/('AMB-Source Data'!C19+'AMB-Source Data'!C20+'AMB-Source Data'!C21+'AMB-Source Data'!C22+'AMB-Source Data'!C23) -> 0.46486276 | C17: ='AMB-Source Data'!D14/('AMB-Source Data'!D19+'AMB-Source Data'!D20+'AMB-Source Data'!D21+'AMB-Source Data'!D22+'AMB-Source Data'!D23) -> 0.38694758
A18: Right-of-use assets | B18: ='AMB-Source Data'!C15/('AMB-Source Data'!C19+'AMB-Source Data'!C20+'AMB-Source Data'!C21+'AMB-Source Data'!C22+'AMB-Source Data'!C23) -> 0.020395485 | C18: ='AMB-Source Data'!D15/('AMB-Source Data'!D19+'AMB-Source Data'!D20+'AMB-Source Data'!D21+'AMB-Source Data'!D22+'AMB-Source Data'!D23) -> 0.022626812
A19: Capital work in progress | B19: ='AMB-Source Data'!C16/('AMB-Source Data'!C19+'AMB-Source Data'!C20+'AMB-Source Data'!C21+'AMB-Source Data'!C22+'AMB-Source Data'!C23) -> 0.12494057 | C19: ='AMB-Source Data'!D16/('AMB-Source Data'!D19+'AMB-Source Data'!D20+'AMB-Source Data'!D21+'AMB-Source Data'!D22+'AMB-Source Data'!D23) -> 0.15127676
A20: Goodwill | B20: ='AMB-Source Data'!C17/('AMB-Source Data'!C19+'AMB-Source Data'!C20+'AMB-Source Data'!C21+'AMB-Source Data'!C22+'AMB-Source Data'!C23) -> 0.18628959 | C20: ='AMB-Source Data'!D17/('AMB-Source Data'!D19+'AMB-Source Data'!D20+'AMB-Source Data'!D21+'AMB-Source Data'!D22+'AMB-Source Data'!D23) -> 0.16903885
A21: Other intangible assets | B21: ='AMB-Source Data'!C18/('AMB-Source Data'!C19+'AMB-Source Data'!C20+'AMB-Source Data'!C21+'AMB-Source Data'!C22+'AMB-Source Data'!C23) -> 0.12973234 | C21: ='AMB-Source Data'!D18/('AMB-Source Data'!D19+'AMB-Source Data'!D20+'AMB-Source Data'!D21+'AMB-Source Data'!D22+'AMB-Source Data'!D23) -> 0.082014237
A22: Equity attributable to owners | B22: ='AMB-Source Data'!C19/('AMB-Source Data'!C19+'AMB-Source Data'!C20+'AMB-Source Data'!C21+'AMB-Source Data'!C22+'AMB-Source Data'!C23) -> 0.81619514 | C22: ='AMB-Source Data'!D19/('AMB-Source Data'!D19+'AMB-Source Data'!D20+'AMB-Source Data'!D21+'AMB-Source Data'!D22+'AMB-Source Data'!D23) -> 0.82765786
A23: Non-controlling interest | B23: ='AMB-Source Data'!C20/('AMB-Source Data'!C19+'AMB-Source Data'!C20+'AMB-Source Data'!C21+'AMB-Source Data'!C22+'AMB-Source Data'!C23) -> 0.17189585 | C23: ='AMB-Source Data'!D20/('AMB-Source Data'!D19+'AMB-Source Data'!D20+'AMB-Source Data'!D21+'AMB-Source Data'!D22+'AMB-Source Data'!D23) -> 0.16016182
A24: Borrowings, non-current | B24: ='AMB-Source Data'!C21/('AMB-Source Data'!C19+'AMB-Source Data'!C20+'AMB-Source Data'!C21+'AMB-Source Data'!C22+'AMB-Source Data'!C23) -> 0.00061599042 | C24: ='AMB-Source Data'!D21/('AMB-Source Data'!D19+'AMB-Source Data'!D20+'AMB-Source Data'!D21+'AMB-Source Data'!D22+'AMB-Source Data'!D23) -> 0.00022228885
A25: Lease liabilities, total | B25: ='AMB-Source Data'!C23/('AMB-Source Data'!C19+'AMB-Source Data'!C20+'AMB-Source Data'!C21+'AMB-Source Data'!C22+'AMB-Source Data'!C23) -> 0.011183135 | C25: ='AMB-Source Data'!D23/('AMB-Source Data'!D19+'AMB-Source Data'!D20+'AMB-Source Data'!D21+'AMB-Source Data'!D22+'AMB-Source Data'!D23) -> 0.011766016
A27: Two lines deserve attention. Profit for the year runs at roughly 14% of revenue while EBITDA runs at 16%, which is impossible on normal taxation and is the visible fingerprint of the net tax CREDIT. Second, goodwill and other intangibles together account for close to a third of capital employed. That is capital shareholders paid for which earns no separate return, and it is why return on invested capital including goodwill never reaches the cost of capital in the forecast. Only two years are shown because the annual report provides only two on a consolidated basis; earlier consolidated years exist only in broker research, which is not an authorised source.

Sheet AMB-Ratios
A1: Ratio Analysis: Ambuja Cements (consolidated)
A2: Returns use the statutory tax rate of 25.168%, never the reported effective rate, which is negative.
A4: Ratio | B4: FY2025-26 | C4: FY2024-25 restated
A5: Profitability
A6: EBITDA margin | B6: =('AMB-Source Data'!C8+'AMB-Source Data'!C6+'AMB-Source Data'!C7-'AMB-Source Data'!C4)/('AMB-Source Data'!C2+'AMB-Source Data'!C3) -> 0.16133022 | C6: =('AMB-Source Data'!D8+'AMB-Source Data'!D6+'AMB-Source Data'!D7-'AMB-Source Data'!D4)/('AMB-Source Data'!D2+'AMB-Source Data'!D3) -> 0.16933992
A7: EBIT margin | B7: =(('AMB-Source Data'!C8+'AMB-Source Data'!C6+'AMB-Source Data'!C7-'AMB-Source Data'!C4)-'AMB-Source Data'!C7)/('AMB-Source Data'!C2+'AMB-Source Data'!C3) -> 0.073509532 | C7: =(('AMB-Source Data'!D8+'AMB-Source Data'!D6+'AMB-Source Data'!D7-'AMB-Source Data'!D4)-'AMB-Source Data'!D7)/('AMB-Source Data'!D2+'AMB-Source Data'!D3) -> 0.10433507
A8: NOPAT at statutory tax | B8: =(('AMB-Source Data'!C8+'AMB-Source Data'!C6+'AMB-Source Data'!C7-'AMB-Source Data'!C4)-'AMB-Source Data'!C7)*(1-'AMB-Assumptions'!$B$35) -> 2236.4142 | C8: =(('AMB-Source Data'!D8+'AMB-Source Data'!D6+'AMB-Source Data'!D7-'AMB-Source Data'!D4)-'AMB-Source Data'!D7)*(1-'AMB-Assumptions'!$B$35) -> 2758.9286
A9: ROIC including goodwill | B9: =(('AMB-Source Data'!C8+'AMB-Source Data'!C6+'AMB-Source Data'!C7-'AMB-Source Data'!C4)-'AMB-Source Data'!C7)*(1-'AMB-Assumptions'!$B$35)/('AMB-Source Data'!C14+'AMB-Source Data'!C15+'AMB-Source Data'!C16+'AMB-Source Data'!C17+'AMB-Source Data'!C18) -> 0.033207076 | C9: =(('AMB-Source Data'!D8+'AMB-Source Data'!D6+'AMB-Source Data'!D7-'AMB-Source Data'!D4)-'AMB-Source Data'!D7)*(1-'AMB-Assumptions'!$B$35)/('AMB-Source Data'!D14+'AMB-Source Data'!D15+'AMB-Source Data'!D16+'AMB-Source Data'!D17+'AMB-Source Data'!D18) -> 0.052491931
A10: ROIC excluding goodwill | B10: =(('AMB-Source Data'!C8+'AMB-Source Data'!C6+'AMB-Source Data'!C7-'AMB-Source Data'!C4)-'AMB-Source Data'!C7)*(1-'AMB-Assumptions'!$B$35)/('AMB-Source Data'!C14+'AMB-Source Data'!C15+'AMB-Source Data'!C16) -> 0.050405018 | C10: =(('AMB-Source Data'!D8+'AMB-Source Data'!D6+'AMB-Source Data'!D7-'AMB-Source Data'!D4)-'AMB-Source Data'!D7)*(1-'AMB-Assumptions'!$B$35)/('AMB-Source Data'!D14+'AMB-Source Data'!D15+'AMB-Source Data'!D16) -> 0.075988827
A11: Return on equity (reported, owners) | B11: ='AMB-Source Data'!C11/'AMB-Source Data'!C19 -> 0.079669646 | C11: ='AMB-Source Data'!D11/'AMB-Source Data'!D19 -> 0.080313302
A12: MEMO: reported effective tax rate | B12: =('AMB-Source Data'!C10-('AMB-Source Data'!C11+'AMB-Source Data'!C12))/'AMB-Source Data'!C10 -> -0.70884299 | C12: =('AMB-Source Data'!D10-('AMB-Source Data'!D11+'AMB-Source Data'!D12))/'AMB-Source Data'!D10 -> 0.13263987
A14: Per tonne economics (FY2025-26 only, volume not disclosed for the prior year)
A15: Sales volume (mn tonnes) | B15: ='AMB-Source Data'!C13 -> 74
A16: Realisation per tonne (Rs) | B16: =('AMB-Source Data'!C2+'AMB-Source Data'!C3)*10/'AMB-Source Data'!C13 -> 5494.0108
A17: EBITDA per tonne (Rs) | B17: =('AMB-Source Data'!C8+'AMB-Source Data'!C6+'AMB-Source Data'!C7-'AMB-Source Data'!C4)*10/'AMB-Source Data'!C13 -> 886.35
A18: Capacity utilisation | B18: ='AMB-Source Data'!C13/'AMB-Assumptions'!$B$6 -> 0.67889908
A20: Asset composition
A21: Goodwill and intangibles, percent of invested capital | B21: =('AMB-Source Data'!C17+'AMB-Source Data'!C18)/('AMB-Source Data'!C14+'AMB-Source Data'!C15+'AMB-Source Data'!C16+'AMB-Source Data'!C17+'AMB-Source Data'!C18) -> 0.34119504 | C21: =('AMB-Source Data'!D17+'AMB-Source Data'!D18)/('AMB-Source Data'!D14+'AMB-Source Data'!D15+'AMB-Source Data'!D16+'AMB-Source Data'!D17+'AMB-Source Data'!D18) -> 0.30921515
A22: CWIP, percent of gross operating assets | B22: ='AMB-Source Data'!C16/('AMB-Source Data'!C14+'AMB-Source Data'!C15+'AMB-Source Data'!C16) -> 0.20475387 | C22: ='AMB-Source Data'!D16/('AMB-Source Data'!D14+'AMB-Source Data'!D15+'AMB-Source Data'!D16) -> 0.2697271
A23: Revenue to operating fixed assets | B23: =('AMB-Source Data'!C2+'AMB-Source Data'!C3)/('AMB-Source Data'!C14+'AMB-Source Data'!C15+'AMB-Source Data'!C16) -> 0.91631071 | C23: =('AMB-Source Data'!D2+'AMB-Source Data'!D3)/('AMB-Source Data'!D14+'AMB-Source Data'!D15+'AMB-Source Data'!D16) -> 0.97326716
A25: Leverage and coverage
A26: Debt to equity | B26: =('AMB-Source Data'!C21+'AMB-Source Data'!C22+'AMB-Source Data'!C23)/'AMB-Source Data'!C19 -> 0.014590886 | C26: =('AMB-Source Data'!D21+'AMB-Source Data'!D22+'AMB-Source Data'!D23)/'AMB-Source Data'!D19 -> 0.014716609
A27: Net debt to EBITDA | B27: =('AMB-Source Data'!C21+'AMB-Source Data'!C22+'AMB-Source Data'!C23-'AMB-Source Data'!C24-'AMB-Source Data'!C25-'AMB-Source Data'!C26)/('AMB-Source Data'!C8+'AMB-Source Data'!C6+'AMB-Source Data'!C7-'AMB-Source Data'!C4) -> -0.0141287 | C27: =('AMB-Source Data'!D21+'AMB-Source Data'!D22+'AMB-Source Data'!D23-'AMB-Source Data'!D24-'AMB-Source Data'!D25-'AMB-Source Data'!D26)/('AMB-Source Data'!D8+'AMB-Source Data'!D6+'AMB-Source Data'!D7-'AMB-Source Data'!D4) -> -1.2042073
A28: Interest coverage (EBIT / finance costs) | B28: =(('AMB-Source Data'!C8+'AMB-Source Data'!C6+'AMB-Source Data'!C7-'AMB-Source Data'!C4)-'AMB-Source Data'!C7)/'AMB-Source Data'!C6 -> 13.365145 | C28: =(('AMB-Source Data'!D8+'AMB-Source Data'!D6+'AMB-Source Data'!D7-'AMB-Source Data'!D4)-'AMB-Source Data'!D7)/'AMB-Source Data'!D6 -> 17.0734
A29: Minority share of group profit | B29: ='AMB-Source Data'!C12/('AMB-Source Data'!C11+'AMB-Source Data'!C12) -> 0.16123596 | C29: ='AMB-Source Data'!D12/('AMB-Source Data'!D11+'AMB-Source Data'!D12) -> 0.18718644
A31: Read the two ROIC rows together. Excluding goodwill the business earns a mediocre return; including it, the return is far below the 11.03% cost of capital. Goodwill is capital shareholders paid, so the second number is the one that matters to them and the first is the one that measures the plants. The memo tax rate row shows why nothing in this workbook uses the reported effective rate. And the minority share row quantifies how much of group profit does not belong to Ambuja shareholders, which is the leakage the pending merger is designed to remove.

Sheet AMB-Assumptions
A1: Assumptions
A3: Net working capital, opening | B3: -139.4 | M3: Consolidated current assets excluding cash and investments, less current liabilities excluding borrowings and leases.
A4: Opening position, FY2025-26 consolidated actual
A5: Cement sales volume (mn T) | B5: 74 | M5: From the Growth Trajectory highlights.
A6: Capacity (MTPA) | B6: 109 | M6: Company stated current capacity.
A7: Opening utilisation | B7: =B5/B6 -> 0.67889908 | M7: Far below UltraTech's 82%. Spare capacity is the whole investment case.
A8: EBITDA per tonne (Rs) | B8: 886.35 | M8: Rs 6,559 crore over 74 million tonnes.
A9: Realisation per tonne (Rs) | B9: 5494.01 | M9: Rs 40,656 crore over 74 million tonnes.
A10: Operating fixed assets (PPE, ROU, CWIP) | B10: 44368.88 | M10: Excludes goodwill and intangibles, which are held separately.
A11: Goodwill and other intangibles | B11: 22978.64 | M11: From acquisitions. In invested capital, but NOT grown at g in the terminal.
A13: Market and capital structure
A14: Market capitalisation | B14: 99095 | M14: As disclosed, 30 March 2026 close.
A15: Shares outstanding (crore) | B15: 247.18 | M15: Share capital Rs 494.36 cr at Rs 2 face value.
A16: Borrowings and lease liabilities | B16: 865.93 | M16: Rs 52.78 cr borrowings plus Rs 813.15 cr leases. Ambuja is effectively debt free.
A17: Cash, bank and current investments | B17: 958.6 | M17: Net cash position of about Rs 93 crore.
A18: Non-controlling interest | B18: 12498.92 | M18: Book value. Deducted in the bridge because consolidated flows include 100% of partly owned subsidiaries.
A20: Tax credit of Rs 2,338 crore: the three drivers, adjusted explicitly
A21: Driver 1: litigation provisions released | B21: 0 | M21: Rs 1,251 crore of earlier year provisions reversed after favourable High Court decisions. The PROVISION REVERSAL itself has no valuation impact and the adjustment here is deliberately zero: it was a provision for disputed income tax sitting in the tax line, and reversing a liability that was never paid changes reported profit without changing cash. Because this model taxes EBIT at the statutory rate throughout, the credit was never in the cash flows to begin with. BUT SEE THE NEXT ROW: part of the disputed tax WAS paid in cash.
A22: Driver 1a: tax paid under protest, recoverable | B22: 614.1 | M22: CONSOLIDATED non-current duty and taxes paid under protest against various disputes (Note 53): Rs 614.10 crore at 31 March 2026, against Rs 628.88 crore a year earlier. This is real cash Ambuja has already handed over and carries as an asset pending appeal, and favourable rulings turn it into a refund. It sits in other non-current assets, which is OUTSIDE the operating invested capital used in this model, so it was being missed entirely. Added to the bridge as a non-operating asset. The current portion of Rs 10.56 crore is already inside net working capital and is NOT added again.
A23: Driver 2: deferred tax liabilities, deducted | B23: 3466.33 | M23: Net consolidated deferred tax liability at 31 March 2026. Treated as a real liability and deducted in the bridge as a ONE TIME drop, not amortised over the forecast. The logic: a deferred tax liability means cash tax paid has lagged book tax, so as it unwinds cash tax exceeds book tax and free cash flow falls. Taking it as a single deduction at the valuation date rather than spreading it avoids pretending to know the timing. This also satisfies liability consistency: if it is treated as a liability it must appear in the bridge.
A24: Driver 3: memo, deferred tax asset on losses and unabsorbed depreciation | B24: 345.78 | M24: CONSOLIDATED figure. The note is headed Unabsorbed depreciation AND Business Losses together, so this single balance already covers BOTH; there is no separate larger business loss pool sitting behind it. Section 72A lets an amalgamated company carry forward the accumulated losses and unabsorbed depreciation of the transferor. Two things follow. First, this is the only one of the three drivers with genuine forward cash value, and it implies roughly Rs 1,374 crore of shelter at the statutory rate. Second, and more important, it is SHRINKING: Rs 509.66 crore at the start of the year, Rs 163.88 crore consumed during FY2025-26, Rs 345.78 crore left. The shelter is being used up, not built. MEMO ONLY, not added separately, because Driver 2 is the NET deferred tax position and this asset is already netted inside it. An earlier draft used the STANDALONE figure of Rs 280.27 crore here, which was the wrong basis for a consolidated model.
A26: Cost of capital
A27: Indian 10 year G-Sec yield | B27: 0.0685 | M27: SOURCED AND DATE MATCHED. FBIL 10-Year G-Sec Par Yield, week ended 20 March 2026, from the RBI Ratios and Rates release dated 27 March 2026. This is the last weekly print before the 31 March 2026 valuation date, so the risk free rate, the market capitalisation and the balance sheet are all struck on the same window. Nearby prints for context: 6.74% on 13 March, 6.76% on 6 March, 6.71% on 27 February, and 6.65% a year earlier in March 2025.
A28: India sovereign default spread | B28: 0.0187 | M28: Damodaran, January 2026.
A29: Risk free rate (rupee, default free) | B29: =B27-B28 -> 0.0498
A30: India equity risk premium | B30: 0.0708 | M30: Damodaran, January 2026.
A31: Unlevered beta, Building Materials | B31: 0.9 | M31: Damodaran Global, cash corrected.
A32: Market debt to equity | B32: 0.008738 | M32: Rs 865.93 cr over Rs 99,095 cr.
A33: Levered beta (bottom up) | B33: =B31*(1+(1-B$3*0+0.25168)*B32) -> 0.90984346
A34: Pre tax cost of debt | B34: 0.08 | M34: Nominal. Barely matters at this leverage.
A35: Statutory tax rate | B35: 0.25168 | M35: Section 115BAA. The reported effective rate is negative and unusable.
A37: Terminal
A38: Long run real GDP growth | B38: 0.065 | M38: Owned assumption.
A39: Long run inflation | B39: 0.04 | M39: RBI CPI target.
A40: Nominal GDP growth | B40: =(1+B38)*(1+B39)-1 -> 0.1076
A41: Terminal growth as a fraction of nominal GDP | B41: 0.65 | M41: 65.0% of nominal GDP, giving 6.99%. RAISED from 46.5% to reflect India's infrastructure runway, which is a genuine medium term demand driver. The HARD CONSTRAINT is that terminal growth can never exceed nominal GDP of 10.76%: a company growing faster than the economy forever eventually becomes larger than the economy. A peer multiple of 19.4x implies 10.99%, which breaches that constraint and is the basis on which this model rejects the peer multiple. Adopting 10.99% ourselves would contradict our own central argument. The same fraction is used for both companies so the two are treated consistently.
A42: Terminal growth rate | B42: =B40*B41 -> 0.06994
A44: Forecast drivers, FY2026-27 to FY2035-36
A45: Driver | C45: FY27 | D45: FY28 | E45: FY29 | F45: FY30 | G45: FY31 | H45: FY32 | I45: FY33 | J45: FY34 | K45: FY35 | L45: FY36
A46: Capacity (MTPA) | C46: 112 | D46: 116 | E46: 119 | F46: 121 | G46: 123 | H46: 125 | I46: 127 | J46: 129 | K46: 131 | L46: 133 | M46: Company targets 119 MTPA. Beyond that this assumes modest brownfield addition only.
...

Sheet AMB-P&L
A1: Line item | B1: Unit | C1: FY27 | D1: FY28 | E1: FY29 | F1: FY30 | G1: FY31 | H1: FY32 | I1: FY33 | J1: FY34 | K1: FY35 | L1: FY36
A2: Capacity | B2: MTPA | C2: ='AMB-Assumptions'!C46 -> 112 | D2: ='AMB-Assumptions'!D46 -> 116 | E2: ='AMB-Assumptions'!E46 -> 119 | F2: ='AMB-Assumptions'!F46 -> 121 | G2: ='AMB-Assumptions'!G46 -> 123 | H2: ='AMB-Assumptions'!H46 -> 125 | I2: ='AMB-Assumptions'!I46 -> 127 | J2: ='AMB-Assumptions'!J46 -> 129 | ... L2: ='AMB-Assumptions'!L46 -> 133
A3: Utilisation | B3: % | C3: ='AMB-Assumptions'!C47 -> 0.7 | D3: ='AMB-Assumptions'!D47 -> 0.725 | E3: ='AMB-Assumptions'!E47 -> 0.75 | F3: ='AMB-Assumptions'!F47 -> 0.775 | G3: ='AMB-Assumptions'!G47 -> 0.795 | H3: ='AMB-Assumptions'!H47 -> 0.81 | I3: ='AMB-Assumptions'!I47 -> 0.825 | J3: ='AMB-Assumptions'!J47 -> 0.835 | ... L3: ='AMB-Assumptions'!L47 -> 0.85
A4: Sales volume | B4: mn T | C4: =C2*C3 -> 78.4 | D4: =D2*D3 -> 84.1 | E4: =E2*E3 -> 89.25 | F4: =F2*F3 -> 93.775 | G4: =G2*G3 -> 97.785 | H4: =H2*H3 -> 101.25 | I4: =I2*I3 -> 104.775 | J4: =J2*J3 -> 107.715 | ... L4: =L2*L3 -> 113.05
A5: Realisation per tonne | B5: Rs/t | C5: ='AMB-Assumptions'!$B$9*(1+'AMB-Assumptions'!C48) -> 5757.7225 | D5: =C5*(1+'AMB-Assumptions'!D48) -> 5988.0314 | E5: =D5*(1+'AMB-Assumptions'!E48) -> 6179.6484 | F5: =E5*(1+'AMB-Assumptions'!F48) -> 6327.9599 | G5: =F5*(1+'AMB-Assumptions'!G48) -> 6454.5191 | H5: =G5*(1+'AMB-Assumptions'!H48) -> 6557.7914 | I5: =H5*(1+'AMB-Assumptions'!I48) -> 6649.6005 | J5: =I5*(1+'AMB-Assumptions'!J48) -> 6729.3957 | K5: =J5*(1+'AMB-Assumptions'!K48) -> 6810.1485 | L5: =K5*(1+'AMB-Assumptions'!L48) -> 6891.8703
A6: Revenue | B6: Rs cr | C6: =C4*C5/10 -> 45140.544 | D6: =D4*D5/10 -> 50359.344 | E6: =E4*E5/10 -> 55153.362 | F6: =F4*F5/10 -> 59340.444 | G6: =G4*G5/10 -> 63115.515 | H6: =H4*H5/10 -> 66397.638 | I6: =I4*I5/10 -> 69671.19 | J6: =J4*J5/10 -> 72485.686 | ... L6: =L4*L5/10 -> 77912.593
A8: Standalone share of revenue | B8: % | C8: ='AMB-Assumptions'!C49 -> 0.615 | D8: ='AMB-Assumptions'!D49 -> 0.613 | E8: ='AMB-Assumptions'!E49 -> 0.611 | F8: ='AMB-Assumptions'!F49 -> 0.609 | G8: ='AMB-Assumptions'!G49 -> 0.607 | H8: ='AMB-Assumptions'!H49 -> 0.605 | I8: ='AMB-Assumptions'!I49 -> 0.604 | J8: ='AMB-Assumptions'!J49 -> 0.603 | ... L8: ='AMB-Assumptions'!L49 -> 0.6
A9: Standalone revenue | B9: Rs cr | C9: =C6*C8 -> 27761.435 | D9: =D6*D8 -> 30870.278 | E9: =E6*E8 -> 33698.704 | F9: =F6*F8 -> 36138.331 | G9: =G6*G8 -> 38311.118 | H9: =H6*H8 -> 40170.571 | I9: =I6*I8 -> 42081.398 | J9: =J6*J8 -> 43708.869 | ... L9: =L6*L8 -> 46747.556
A10: Standalone EBITDA margin | B10: % | C10: ='AMB-Assumptions'!C50 -> 0.13 | D10: ='AMB-Assumptions'!D50 -> 0.142 | E10: ='AMB-Assumptions'!E50 -> 0.152 | F10: ='AMB-Assumptions'!F50 -> 0.16 | G10: ='AMB-Assumptions'!G50 -> 0.167 | H10: ='AMB-Assumptions'!H50 -> 0.173 | I10: ='AMB-Assumptions'!I50 -> 0.178 | J10: ='AMB-Assumptions'!J50 -> 0.183 | ... L10: ='AMB-Assumptions'!L50 -> 0.19
A11: Standalone EBITDA | B11: Rs cr | C11: =C9*C10 -> 3608.9865 | D11: =D9*D10 -> 4383.5794 | E11: =E9*E10 -> 5122.203 | F11: =F9*F10 -> 5782.1329 | G11: =G9*G10 -> 6397.9567 | H11: =H9*H10 -> 6949.5088 | I11: =I9*I10 -> 7490.4889 | J11: =J9*J10 -> 7998.723 | ... L11: =L9*L10 -> 8882.0356
A13: Subsidiary revenue | B13: Rs cr | C13: =C6-C9 -> 17379.11 | D13: =D6-D9 -> 19489.066 | E13: =E6-E9 -> 21454.658 | F13: =F6-F9 -> 23202.114 | G13: =G6-G9 -> 24804.398 | H13: =H6-H9 -> 26227.067 | I13: =I6-I9 -> 27589.791 | J13: =J6-J9 -> 28776.817 | ... L13: =L6-L9 -> 31165.037
A14: Subsidiary EBITDA margin | B14: % | C14: ='AMB-Assumptions'!C51 -> 0.236 | D14: ='AMB-Assumptions'!D51 -> 0.24 | E14: ='AMB-Assumptions'!E51 -> 0.244 | F14: ='AMB-Assumptions'!F51 -> 0.247 | G14: ='AMB-Assumptions'!G51 -> 0.25 | H14: ='AMB-Assumptions'!H51 -> 0.252 | I14: ='AMB-Assumptions'!I51 -> 0.254 | J14: ='AMB-Assumptions'!J51 -> 0.256 | ... L14: ='AMB-Assumptions'!L51 -> 0.26
A15: Subsidiary EBITDA | B15: Rs cr | C15: =C13*C14 -> 4101.4698 | D15: =D13*D14 -> 4677.3759 | E15: =E13*E14 -> 5234.9365 | F15: =F13*F14 -> 5730.9221 | G15: =G13*G14 -> 6201.0994 | H15: =H13*H14 -> 6609.2209 | I15: =I13*I14 -> 7007.8069 | J15: =J13*J14 -> 7366.8653 | ... L15: =L13*L14 -> 8102.9097
A17: EBITDA | B17: Rs cr | C17: =C11+C15 -> 7710.4564 | D17: =D11+D15 -> 9060.9553 | E17: =E11+E15 -> 10357.14 | F17: =F11+F15 -> 11513.055 | G17: =G11+G15 -> 12599.056 | H17: =H11+H15 -> 13558.73 | I17: =I11+I15 -> 14498.296 | J17: =J11+J15 -> 15365.588 | ... L17: =L11+L15 -> 16984.945
A18: Memo: consolidated EBITDA margin | B18: % | C18: =C17/C6 -> 0.17081 | D18: =D17/D6 -> 0.179926 | E18: =E17/E6 -> 0.187788 | F18: =F17/F6 -> 0.194017 | G18: =G17/G6 -> 0.199619 | H18: =H17/H6 -> 0.204205 | I18: =I17/I6 -> 0.208096 | J18: =J17/J6 -> 0.211981 | ... L18: =L17/L6 -> 0.218
A19: Memo: EBITDA per tonne | B19: Rs/t | C19: =C17*10/C4 -> 983.47658 | D19: =D17*10/D4 -> 1077.4025 | E19: =E17*10/E4 -> 1160.4638 | F19: =F17*10/F4 -> 1227.7318 | G19: =G17*10/G4 -> 1288.4447 | H19: =H17*10/H4 -> 1339.1338 | I19: =I17*10/I4 -> 1383.7553 | J19: =J17*10/J4 -> 1426.504 | ... L19: =L17*10/L4 -> 1502.4277
A21: Opening operating fixed assets | B21: Rs cr | C21: ='AMB-Assumptions'!$B$10 -> 44368.88 | D21: =C24 -> 50319.37 | E21: =D24 -> 55293.82 | F21: =E24 -> 59370.314 | G21: =F24 -> 62620.689 | H21: =G24 -> 65111.034 | I21: =H24 -> 67402.151 | J21: =I24 -> 69509.979 | K21: =J24 -> 71449.181 | L21: =K24 -> 73233.246
A22: Depreciation and amortisation | B22: Rs cr | C22: =C21*'AMB-Assumptions'!C53 -> 3549.5104 | D22: =D21*'AMB-Assumptions'!D53 -> 4025.5496 | E22: =E21*'AMB-Assumptions'!E53 -> 4423.5056 | F22: =F21*'AMB-Assumptions'!F53 -> 4749.6252 | G22: =G21*'AMB-Assumptions'!G53 -> 5009.6551 | H22: =H21*'AMB-Assumptions'!H53 -> 5208.8827 | I22: =I21*'AMB-Assumptions'!I53 -> 5392.1721 | J22: =J21*'AMB-Assumptions'!J53 -> 5560.7983 | ... L22: =L21*'AMB-Assumptions'!L53 -> 5858.6597
A23: Capital expenditure | B23: Rs cr | C23: ='AMB-Assumptions'!C52 -> 9500 | D23: ='AMB-Assumptions'!D52 -> 9000 | E23: ='AMB-Assumptions'!E52 -> 8500 | F23: ='AMB-Assumptions'!F52 -> 8000 | G23: ='AMB-Assumptions'!G52 -> 7500 | H23: ='AMB-Assumptions'!H52 -> 7500 | I23: ='AMB-Assumptions'!I52 -> 7500 | J23: ='AMB-Assumptions'!J52 -> 7500 | ... L23: ='AMB-Assumptions'!L52 -> 7500
A24: Closing operating fixed assets | B24: Rs cr | C24: =C21+C23-C22 -> 50319.37 | D24: =D21+D23-D22 -> 55293.82 | E24: =E21+E23-E22 -> 59370.314 | F24: =F21+F23-F22 -> 62620.689 | G24: =G21+G23-G22 -> 65111.034 | H24: =H21+H23-H22 -> 67402.151 | I24: =I21+I23-I22 -> 69509.979 | J24: =J21+J23-J22 -> 71449.181 | ... L24: =L21+L23-L22 -> 74874.587
A25: EBIT | B25: Rs cr | C25: =C17-C22 -> 4160.946 | D25: =D17-D22 -> 5035.4057 | E25: =E17-E22 -> 5933.6339 | F25: =F17-F22 -> 6763.4298 | G25: =G17-G22 -> 7589.4009 | H25: =H17-H22 -> 8349.847 | I25: =I17-I22 -> 9106.1237 | J25: =J17-J22 -> 9804.7899 | ... L25: =L17-L22 -> 11126.286
A26: NOPAT (EBIT at statutory tax) | B26: Rs cr | C26: =C25*(1-'AMB-Assumptions'!$B$35) -> 3113.7191 | D26: =D25*(1-'AMB-Assumptions'!$B$35) -> 3768.0948 | E26: =E25*(1-'AMB-Assumptions'!$B$35) -> 4440.2569 | F26: =F25*(1-'AMB-Assumptions'!$B$35) -> 5061.2098 | G26: =G25*(1-'AMB-Assumptions'!$B$35) -> 5679.3005 | H26: =H25*(1-'AMB-Assumptions'!$B$35) -> 6248.3575 | I26: =I25*(1-'AMB-Assumptions'!$B$35) -> 6814.2945 | J26: =J25*(1-'AMB-Assumptions'!$B$35) -> 7337.1204 | ... L26: =L25*(1-'AMB-Assumptions'!$B$35) -> 8326.0221
A27: Net working capital (closing) | B27: Rs cr | C27: =C6*'AMB-Assumptions'!C54 -> -153.47785 | D27: =D6*'AMB-Assumptions'!D54 -> -171.22177 | E27: =E6*'AMB-Assumptions'!E54 -> -187.52143 | F27: =F6*'AMB-Assumptions'!F54 -> -201.75751 | G27: =G6*'AMB-Assumptions'!G54 -> -214.59275 | H27: =H6*'AMB-Assumptions'!H54 -> -225.75197 | I27: =I6*'AMB-Assumptions'!I54 -> -236.88204 | J27: =J6*'AMB-Assumptions'!J54 -> -246.45133 | ... L27: =L6*'AMB-Assumptions'!L54 -> -264.90282
A28: Change in net working capital | B28: Rs cr | C28: =C27-'AMB-Assumptions'!$B$3 -> -14.07785 | D28: =D27-C27 -> -17.743919 | E28: =E27-D27 -> -16.299661 | F28: =F27-E27 -> -14.236081 | G28: =G27-F27 -> -12.835242 | H28: =H27-G27 -> -11.159218 | I28: =I27-H27 -> -11.130074 | J28: =J27-I27 -> -9.5692885 | K28: =K27-J27 -> -9.8574584 | L28: =L27-K27 -> -8.594026
A29: FCFF | B29: Rs cr | C29: =C26+C22-C23-C28 -> -2822.6927 | D29: =D26+D22-D23-D28 -> -1188.6117 | E29: =E26+E22-E23-E28 -> 380.06219 | F29: =F26+F22-F23-F28 -> 1825.0711 | G29: =G26+G22-G23-G28 -> 3201.7909 | H29: =H26+H22-H23-H28 -> 3968.3995 | I29: =I26+I22-I23-I28 -> 4717.5967 | J29: =J26+J22-J23-J28 -> 5407.488 | ... L29: =L26+L22-L23-L28 -> 6693.2758
A30: Memo: EBITDA margin | B30: % | C30: =IFERROR(C17/C6,"") -> 0.17081 | D30: =IFERROR(D17/D6,"") -> 0.179926 | E30: =IFERROR(E17/E6,"") -> 0.187788 | F30: =IFERROR(F17/F6,"") -> 0.194017 | G30: =IFERROR(G17/G6,"") -> 0.199619 | H30: =IFERROR(H17/H6,"") -> 0.204205 | I30: =IFERROR(I17/I6,"") -> 0.208096 | J30: =IFERROR(J17/J6,"") -> 0.211981 | ... L30: =IFERROR(L17/L6,"") -> 0.218
A32: THIS SHEET IS A BUILD UP, NOT A CONSOLIDATED FORECAST. Revenue is built top down from physical capacity times utilisation times realisation, which disciplines it against the plant the company actually owns. That consolidated revenue is then SPLIT into the standalone parent and the subsidiary block using the FY2025-26 revenue share of 61.6%, and each block carries its own EBITDA margin: the parent starts at 11.7% because Sanghi and Penna sit inside it, the subsidiaries start at 23.3% because ACC and Orient sit outside it. Consolidated EBITDA is the SUM of the two blocks, not an assumed group margin. Free cash flow is negative in the early years, which is what a company at 68% utilisation with Rs 9,085 crore of capital work in progress looks like.
A35: HISTORICAL ACTUALS, for comparison with the forecast above
A36: Line item | B36: Unit | C36: FY25 | D36: FY26
C37: Actual | D37: Actual
A38: Cement sales volume (Mn.T) | D38: 74
A39: Capacity (MTPA) | D39: 109
A40: Capacity utilisation | B40: % | D40: 0.679
A41: Revenue including grants | B41: Rs cr | C41: 35336 | D41: 40656
A42: of which standalone | B42: Rs cr | D42: 25062
A43: of which subsidiaries | B43: Rs cr | D43: 15594
A44: EBITDA (uniform definition) | B44: Rs cr | C44: 5984 | D44: 6559
A45: of which standalone | B45: Rs cr | D45: 2930
A46: of which subsidiaries | B46: Rs cr | D46: 3629
A47: EBITDA margin, consolidated | B47: % | C47: 0.169 | D47: 0.161
...

Sheet AMB-Balance Sheet
A1: Line item | B1: Unit | C1: FY27 | D1: FY28 | E1: FY29 | F1: FY30 | G1: FY31 | H1: FY32 | I1: FY33 | J1: FY34 | K1: FY35 | L1: FY36
A2: Opening operating invested capital | B2: Rs cr | C2: ='AMB-Assumptions'!$B$10+'AMB-Assumptions'!$B$3 -> 44229.48 | D2: =C5 -> 50165.892 | E2: =D5 -> 55122.598 | F2: =E5 -> 59182.793 | G2: =F5 -> 62418.932 | H2: =G5 -> 64896.441 | I2: =H5 -> 67176.399 | J2: =I5 -> 69273.097 | K2: =J5 -> 71202.73 | L2: =K5 -> 72976.938
A3: Add: Capex less depreciation | B3: Rs cr | C3: ='AMB-P&L'!C23-'AMB-P&L'!C22 -> 5950.4896 | D3: ='AMB-P&L'!D23-'AMB-P&L'!D22 -> 4974.4504 | E3: ='AMB-P&L'!E23-'AMB-P&L'!E22 -> 4076.4944 | F3: ='AMB-P&L'!F23-'AMB-P&L'!F22 -> 3250.3748 | G3: ='AMB-P&L'!G23-'AMB-P&L'!G22 -> 2490.3449 | H3: ='AMB-P&L'!H23-'AMB-P&L'!H22 -> 2291.1173 | I3: ='AMB-P&L'!I23-'AMB-P&L'!I22 -> 2107.8279 | J3: ='AMB-P&L'!J23-'AMB-P&L'!J22 -> 1939.2017 | ... L3: ='AMB-P&L'!L23-'AMB-P&L'!L22 -> 1641.3403
A4: Add: Change in net working capital | B4: Rs cr | C4: ='AMB-P&L'!C28 -> -14.07785 | D4: ='AMB-P&L'!D28 -> -17.743919 | E4: ='AMB-P&L'!E28 -> -16.299661 | F4: ='AMB-P&L'!F28 -> -14.236081 | G4: ='AMB-P&L'!G28 -> -12.835242 | H4: ='AMB-P&L'!H28 -> -11.159218 | I4: ='AMB-P&L'!I28 -> -11.130074 | J4: ='AMB-P&L'!J28 -> -9.5692885 | ... L4: ='AMB-P&L'!L28 -> -8.594026
A5: Closing operating invested capital | B5: Rs cr | C5: =SUM(C2:C4) -> 50165.892 | D5: =SUM(D2:D4) -> 55122.598 | E5: =SUM(E2:E4) -> 59182.793 | F5: =SUM(F2:F4) -> 62418.932 | G5: =SUM(G2:G4) -> 64896.441 | H5: =SUM(H2:H4) -> 67176.399 | I5: =SUM(I2:I4) -> 69273.097 | J5: =SUM(J2:J4) -> 71202.73 | ... L5: =SUM(L2:L4) -> 74609.684
A6: Goodwill and intangibles (held flat) | B6: Rs cr | C6: ='AMB-Assumptions'!$B$11 -> 22978.64 | D6: ='AMB-Assumptions'!$B$11 -> 22978.64 | E6: ='AMB-Assumptions'!$B$11 -> 22978.64 | F6: ='AMB-Assumptions'!$B$11 -> 22978.64 | G6: ='AMB-Assumptions'!$B$11 -> 22978.64 | H6: ='AMB-Assumptions'!$B$11 -> 22978.64 | I6: ='AMB-Assumptions'!$B$11 -> 22978.64 | J6: ='AMB-Assumptions'!$B$11 -> 22978.64 | ... L6: ='AMB-Assumptions'!$B$11 -> 22978.64
A7: Total invested capital (opening, incl goodwill) | B7: Rs cr | C7: =C2+C6 -> 67208.12 | D7: =D2+D6 -> 73144.532 | E7: =E2+E6 -> 78101.238 | F7: =F2+F6 -> 82161.433 | G7: =G2+G6 -> 85397.572 | H7: =H2+H6 -> 87875.081 | I7: =I2+I6 -> 90155.039 | J7: =J2+J6 -> 92251.737 | ... L7: =L2+L6 -> 95955.578
A8: NOPAT | B8: Rs cr | C8: ='AMB-P&L'!C26 -> 3113.7191 | D8: ='AMB-P&L'!D26 -> 3768.0948 | E8: ='AMB-P&L'!E26 -> 4440.2569 | F8: ='AMB-P&L'!F26 -> 5061.2098 | G8: ='AMB-P&L'!G26 -> 5679.3005 | H8: ='AMB-P&L'!H26 -> 6248.3575 | I8: ='AMB-P&L'!I26 -> 6814.2945 | J8: ='AMB-P&L'!J26 -> 7337.1204 | ... L8: ='AMB-P&L'!L26 -> 8326.0221
