Workbook

Sheet UTCL-Index
A1: UltraTech Cement Ltd: Business Analysis and Valuation
A2: Standalone basis. Rs crore unless stated. FYE 31 March. Valuation date 31 March 2026.
A4: No. | B4: Sheet | C4: What it contains
A5: 1 | B5: Source-Log | C5: Every input traced to its publisher, with open items and re-source flags marked in red
A6: 2 | B6: Source-Data | C6: Ten year standalone history exactly as published in the FY2025-26 report, plus derived ratios
A7: 3 | B7: Assumptions | C7: Every forecast driver and hardcoded input in one place. Blue on yellow means edit here
A8: 4 | B8: PnL-Forecast | C8: FY2026-27 to FY2030-31 forecast profit and loss built off the assumption drivers
A9: 5 | B9: Invested-Capital | C9: Invested capital roll forward, ROIC history and forecast, reinvestment rate
A10: 6 | B10: Cost-of-Capital | C10: Risk free, ERP, beta, cost of debt, capital structure, WACC and the unlevered rate rho
A11: 7 | B11: FCFF | C11: Enterprise DCF on free cash flow to the firm, discounted at WACC
A12: 8 | B12: CCF | C12: Capital cash flow valuation, discounted at the unlevered rate rho
A13: 9 | B13: APV | C13: Adjusted present value: unlevered value plus the present value of the interest tax shield
A14: 10 | B14: FCFE | C14: Equity DCF on free cash flow to equity, discounted at the cost of equity
A15: 11 | B15: EVA | C15: Economic value added: opening invested capital plus the present value of future EVA
A16: 12 | B16: Reconciliation | C16: Proof that all five methods return the same enterprise and equity value
... A18: 14 | B18: Summary | C18: Valuation summary, football field, and what the market price is implying
A20: Colour convention
B21: Blue | C21: Hardcoded input taken from a published source
B22: Blue on yellow | C22: Assumption or judgement. Change these to test the model
B23: Black | C23: Formula within the sheet
B24: Green | C24: Link to another sheet
A26: Read this before using any number in this workbook
B27: The equity risk premium and beta are now sourced from Damodaran, January 2026. The ONE remaining placeholder is the Indian 10 year G-Sec yield on the Assumptions sheet, which must come from RBI. Note that replacing the earlier invented cost of capital moved the answer very little, which is itself the finding: the discount rate is not what separates this model from the market price.
B28: The terminal value imposes a genuine steady state: reinvestment equals terminal growth times invested capital. This is what makes all five valuation methods reconcile exactly. Do not replace it with a naive FCFF perpetuity.
B29: FY2018-19 and FY2022-23 are shown as Restated in the company's own ten year table. The restatement basis is the company's; it has not been independently verified here.

Sheet UTCL-Audit Log
A1: Source Log
A2: Every input cell in this workbook traces to a row below. Rows marked PLACEHOLDER or RE-SOURCE are open items.
A4: # | B4: Item | C4: Publisher | D4: Source and location | E4: Accessed | F4: Period | G4: Feeds
A5: 1 | B5: Ten year standalone financial highlights | C5: UltraTech Cement Ltd | D5: integrated-and-sustainability-report-2025-26-double-page.pdf, Standalone Financial Highlights | E5: 2026-08-26 | F5: FY2016-17 to FY2025-26 | G5: Source-Data, all rows
A6: 2 | B6: Standalone balance sheet | C6: UltraTech Cement Ltd | D6: Same report, standalone balance sheet. Loan funds 19,617, leases 863, net worth 74,663 all tie to the ten year table. | E6: 2026-08-26 | F6: 31-Mar-2026 | G6: Assumptions, debt and leases
A7: 3 | B7: Capital work in progress | C7: UltraTech Cement Ltd | D7: Same report, Note 02: CWIP Rs 7,871.47 cr (FY25 Rs 5,956.01 cr) | E7: 2026-08-26 | F7: 31-Mar-2026 | G7: Assumptions, productive fixed assets
A8: 4 | B8: Non-current investments note | C8: UltraTech Cement Ltd | D8: Same report: The India Cements Limited, 23,24,16,830 shares, carrying value Rs 8,970.17 cr, holding 74.99% | E8: 2026-08-26 | F8: 31-Mar-2026 | G8: Assumptions, India Cements block
A9: 5 | B9: Market capitalisation and monthly price table | C9: UltraTech Cement Ltd | D9: Same report, Shareholder Information: NSE Rs 3,16,633 cr; March 2026 NSE close Rs 10,745.00. The two tie over 29.468 cr shares. | E9: 2026-08-26 | F9: 30-Mar-2026 | G9: Assumptions, market data
A10: 6 | B10: Unaudited standalone results, Q1 FY2026-27 | C10: UltraTech Cement Ltd | D10: q1fy27results.pdf, standalone results page 10 | E10: 2026-08-26 | F10: Q1 FY27 | G10: Cross-check only
A11: 7 | B11: Regulation 52(4) disclosures | C11: UltraTech Cement Ltd | D11: q1fy27results.pdf page 11: net worth Rs 77,127.12 cr at 30-Jun-26, debt to equity 0.25x. Used only to corroborate the balance sheet. | E11: 2026-08-26 | F11: 30-Jun-2026 | G11: Memo
A12: 8 | B12: India equity risk premium 7.08% | C12: Aswath Damodaran, NYU Stern | D12: Country Default Spreads and Risk Premiums, January 2026. India Baa3: mature market 4.23% plus country risk premium 2.85%. CDS based alternative 5.23%. | E12: 2026-08-26 | F12: Jan-2026 | G12: Cost-of-Capital
A13: 9 | B13: India sovereign default spread 1.87% | C13: Aswath Damodaran, NYU Stern | D13: Same table. Deducted from the G-Sec yield to reach a default free rupee rate. | E13: 2026-08-26 | F13: Jan-2026 | G13: Cost-of-Capital
A14: 10 | B14: Unlevered beta 0.90, Building Materials | C14: Aswath Damodaran, NYU Stern | D14: Betas by Sector (Global), January 2026: 469 firms, unlevered beta corrected for cash. Cash corrected figure used because cash is added back separately at the bridge. | E14: 2026-08-26 | F14: Jan-2026 | G14: Cost-of-Capital
A15: 11 | B15: ASSUMPTION: tax rate 25.168% | C15: Own assumption, verified | D15: Section 115BAA: 22% plus 10% surcharge plus 4% cess. Cross-checked against the reported effective rate of 26.1% in FY2025-26, so no migration path needed. | E15: 2026-08-26 | F15: FY2025-26 | G15: Assumptions
A16: 12 | B16: ASSUMPTION: cost of debt 8.34% | C16: Own assumption | D16: FY2025-26 interest of 1,630 over average loan funds of 19,538. The method prefers a traded bond yield; this is the sanity check version and should be upgraded if UltraTech has listed debt. | E16: 2026-08-26 | F16: FY2025-26 | G16: Cost-of-Capital
... A20: 16 | B20: DERIVED: standalone capacity 172.5 Mn.T | C20: Own derivation | D20: Consolidated 192.3 mtpa less 5.4 overseas less India Cements 14.45. NOT a disclosed figure. Verify against the investor presentation. | E20: 2026-08-26 | F20: FY2025-26 | G20: Assumptions
A21: 17 | B21: OPEN: India Cements market price | C21: NSE | D21: NOT YET SOURCED. India Cements is listed, so asset consistency requires the stake at market value. Model falls back to carrying value while blank. Each Rs 100 on the ICEM price moves UltraTech value by about Rs 79 per share. | F21: 30-Mar-2026 | G21: Assumptions, India Cements
A22: 18 | B22: OPTIONAL: Fama French factors | C22: IIM Ahmedabad | D22: Indian Fama French factor library (Agarwalla, Jacob and Varma) for the alternative cost of equity. Ken French publishes no India dataset; Yahoo Finance is a banned source, so prices must come from NSE. | E22: 2026-08-26 | F22: 1993 onward | G22: Cost-of-Capital, FF Ke cell
A23: 19 | B23: Peer multiples | C23: Peer annual reports | D23: Shree Cement, JK Cement and Ramco Cements: financials and disclosed market caps from their own FY2025-26 reports. See the companion comps workbook. | E23: 2026-08-26 | F23: TTM to Jun-2026 | G23: Summary, football field
A25: Banned sources check: no data anywhere in this workbook comes from moneycontrol, screener.in, Yahoo Finance, investing.com, trendlyne, tijori or Wikipedia. The one non-authorised input is the broker relayed earnings call content flagged above, which is marked for re-sourcing rather than quietly used.
A28: MODEL AUDIT LOG: issues found during the build, and what was done about them
A29: # | B29: Where | C29: Severity | D29: Finding | E29: Valuation impact | F29: Fix applied
A30: 1 | B30: Dashboard, Golden Check 6 | C30: HIGH | D30: Terminal ROIC of 15.8% against a WACC of 11.33% is a permanent 4.5 point spread in perpetuity, which assumes super normal returns forever and contradicts a realised ROIC that FELL from 14.5% to 10.8% over four years. | E30: Overstated value by roughly Rs 1,141 per share | F30: FIXED. A terminal ROIC fade is now wired into the Balance Sheet terminal block and switched ON by default, taking terminal ROIC to WACC plus 0.5%. Value falls from Rs 5,273 to Rs 4,132. The switch is on the Assumptions sheet.
A31: 2 | B31: Entity Build, India Cements | C31: MED | D31: The 74.99% holding in the LISTED India Cements is carried at BOOK value of Rs 8,970 cr, or Rs 385.95 per India Cements share. | E31: Each Rs 100 on the India Cements price moves UltraTech by about Rs 79 per share | F31: PARTIALLY FIXED. A market price override cell exists on the Assumptions sheet and a sensitivity table is now on the Entity Build sheet. The price itself is still to be sourced from NSE.
A32: 3 | B32: Entity Build, basis | C32: MED | D32: UltraTech is valued STANDALONE while Ambuja is valued CONSOLIDATED. Prof. Mohanty's own teaching is explicit that a holding above 50% requires consolidation, and UltraTech holds 74.99% of India Cements. | E32: Omitted subsidiary block is 9.3% of group EBITDA | F32: PARTIALLY FIXED. Consolidated figures are now reconciled on the Entity Build sheet and a what-if consolidation bridge quantifies the omission at roughly Rs 537 per share. A full consolidated rebuild is not possible because consolidated VOLUME and CWIP are not separately disclosed.
A33: 4 | B33: Model build, capital intensity | C33: HIGH | D33: Capex was originally derived from capital intensity, which charged the company a second time for capacity it had already built. | E33: Understated value by roughly one third | F33: FIXED. Capex is now an explicit input anchored to management guidance of about Rs 10,000 cr a year.
A34: 5 | B34: Model build, CWIP | C34: MED | D34: Capital work in progress of Rs 7,871 cr was included in the capital intensity ratio despite earning no revenue. | E34: Understated value by about 14% | F34: FIXED. CWIP is excluded from the intensity ratio but retained inside invested capital, which is what Book 29 section 4.6 requires.
A35: 6 | B35: Cost of capital, risk free rate | C35: MED | D35: The 10 year G-Sec yield was a placeholder at 6.50%. | E35: About 5% of value | F35: FIXED. Replaced with the FBIL 10 year par yield of 6.85% for the week ended 20 March 2026, date matched to the valuation date.
A36: 7 | B36: Beta | C36: LOW | D36: Only a bottom up beta was available; no regression cross check had been run. | E36: None; direction favours conservatism | F36: FIXED. A live regression is now on the Beta sheet using 60 monthly observations. It returns 1.0863 against the bottom up 0.9436. The bottom up figure is retained and the difference disclosed.
A38: Every entry above was found by us during the build, not by a reviewer afterwards. Where an item is marked PARTIALLY FIXED or DOCUMENTED NOT FIXED, the reason is stated and the direction of the residual error is given. Three of the fixes moved the valuation AGAINST our own recommendation, which is recorded deliberately.
A41: SOURCE URLs AND ACCESS DATES
A42: Input | B42: Authoritative source URL | C42: Accessed
A43: Company annual report and financial statements | B43: https://www.ultratechcement.com/investors/investor-reports | C43: 26 Aug 2026
A44: Exchange filings and quarterly results | B44: https://www.nseindia.com/companies-listing/corporate-filings-financial-results | C44: 26 Aug 2026
A45: 10 year G-Sec par yield, FBIL series | B45: https://www.rbi.org.in/Scripts/BS_ViewBulletin.aspx | C45: 26 Aug 2026
A46: Equity risk premium and sovereign default spread | B46: https://pages.stern.nyu.edu/~adamodar/New_Home_Page/datacurrent.html | C46: 26 Aug 2026
A47: Unlevered beta by sector, global | B47: https://pages.stern.nyu.edu/~adamodar/New_Home_Page/datafile/Betas.html | C47: 26 Aug 2026
A48: Historical price series for the beta regression | B48: https://www.nseindia.com/reports-indices-historical-index-data | C48: 26 Aug 2026
A50: These are the AUTHORITATIVE LANDING PAGES from which each input was obtained, with the access date. Deep links to individual PDFs are deliberately not given: they are unstable, and fabricating a precise document URL that was not actually followed would be worse than citing the page that was. Each annual report is identified by name, year and note reference in the rows above, which is sufficient to locate the exact figure. The price series used for the beta regression was supplied with an adjusted close column, a market data vendor convention rather than the exchange bhavcopy format, and is labelled as vendor sourced on the Beta sheet.

Sheet UTCL-Source Data
A1: Line item (standalone, as published) | B1: Unit | C1: 2016-17 | D1: 2017-18 | E1: 2018-19 R | F1: 2019-20 | G1: 2020-21 | H1: 2021-22 | I1: 2022-23 R | J1: 2023-24 | K1: 2024-25 | L1: 2025-26
A2: Grey cement sales (Mn.T) | B2: Mn.T | C2: 48.87 | D2: 59.33 | E2: 80.78 | F2: 77.46 | G2: 81.25 | H2: 88.02 | I2: 100.06 | J2: 112.81 | K2: 125.81 | L2: 140.75
A3: Revenue including operating income | B3: Rs cr | C3: 23891 | D3: 29358 | E3: 39999 | F3: 40649 | G3: 43188 | H3: 50663 | I3: 61237 | J3: 68641 | K3: 71895 | L3: 82170
A4: Operating expenses | B4: Rs cr | C4: 18922 | D4: 23475 | E4: 32920 | F4: 31997 | G4: 32224 | H4: 39727 | I4: 50952 | J4: 56021 | K4: 59599 | L4: 66730
A5: Operating profit (EBITDA) | B5: Rs cr | C5: 4969 | D5: 5883 | E5: 7079 | F5: 8652 | G5: 10965 | H5: 10936 | I5: 10286 | J5: 12620 | K5: 12296 | L5: 15439
A6: Other income | B6: Rs cr | C6: 660 | D6: 600 | E6: 497 | F6: 727 | G6: 789 | H6: 612 | I6: 505 | J6: 662 | K6: 693 | L6: 376
A7: Depreciation and amortisation | B7: Rs cr | C7: 1268 | D7: 1764 | E7: 2321 | F7: 2455 | G7: 2434 | H7: 2457 | I7: 2773 | J7: 3027 | K7: 3739 | L7: 4055
A8: EBIT | B8: Rs cr | C8: 4361 | D8: 4719 | E8: 5255 | F8: 6924 | G8: 9319 | H8: 9091 | I8: 8018 | J8: 10255 | K8: 9250 | L8: 11761
A9: Interest | B9: Rs cr | C9: 571 | D9: 1191 | E9: 1648 | F9: 1704 | G9: 1259 | H9: 798 | I9: 756 | J9: 867 | K9: 1465 | L9: 1630
A10: Profit before tax | B10: Rs cr | C10: 3790 | D10: 3528 | E10: 3606 | F10: 5220 | G10: 8060 | H10: 8293 | I10: 7262 | J10: 9388 | K10: 7785 | L10: 10131
A11: Exceptional items gain/(loss) | B11: Rs cr | C11: -14 | D11: -226 | E11: -114 | F11: 0 | G11: -164 | H11: 0 | I11: 0 | J11: -72 | K11: -88 | L11: -104
A12: Tax expense | B12: Rs cr | C12: 1148 | D12: 1071 | E12: 1080 | F12: -236 | G12: 2554 | H12: 1227 | I12: 2310 | J12: 2411 | K12: 1504 | L12: 2622
A13: Net profit | B13: Rs cr | C13: 2628 | D13: 2231 | E13: 2412 | F13: 5456 | G13: 5342 | H13: 7067 | I13: 4951 | J13: 6905 | K13: 6193 | L13: 7405
... A24: Capital employed | B24: Rs cr | C24: 32955 | D24: 46517 | E24: 59181 | F24: 61548 | G24: 66886 | H24: 65276 | I24: 69369 | J24: 74531 | K24: 98236 | L24: 103649
A26: Derived
A27: EBITDA margin | C27: =IFERROR(C5/C3,"") -> 0.20798627 | D27: =IFERROR(D5/D3,"") -> 0.20038831 | E27: =IFERROR(E5/E3,"") -> 0.17697942 | F27: =IFERROR(F5/F3,"") -> 0.21284656 | G27: =IFERROR(G5/G3,"") -> 0.25388997 | H27: =IFERROR(H5/H3,"") -> 0.21585773 | I27: =IFERROR(I5/I3,"") -> 0.16797034 | J27: =IFERROR(J5/J3,"") -> 0.18385513 | ... L27: =IFERROR(L5/L3,"") -> 0.18789096
A28: Revenue growth | D28: =IFERROR(D3/C3-1,"") -> 0.22883094 | E28: =IFERROR(E3/D3-1,"") -> 0.36245657 | F28: =IFERROR(F3/E3-1,"") -> 0.016250406 | G28: =IFERROR(G3/F3-1,"") -> 0.062461561 | H28: =IFERROR(H3/G3-1,"") -> 0.17308049 | I28: =IFERROR(I3/H3-1,"") -> 0.20871247 | J28: =IFERROR(J3/I3-1,"") -> 0.12090729 | K28: =IFERROR(K3/J3-1,"") -> 0.047406069 | L28: =IFERROR(L3/K3-1,"") -> 0.14291675
A29: Realisation per tonne (Rs) | C29: =IFERROR(C3*10000000/(C2*1000000),"") -> 4888.6843 | D29: =IFERROR(D3*10000000/(D2*1000000),"") -> 4948.2555 | E29: =IFERROR(E3*10000000/(E2*1000000),"") -> 4951.5969 | F29: =IFERROR(F3*10000000/(F2*1000000),"") -> 5247.7408 | G29: =IFERROR(G3*10000000/(G2*1000000),"") -> 5315.4462 | H29: =IFERROR(H3*10000000/(H2*1000000),"") -> 5755.8509 | I29: =IFERROR(I3*10000000/(I2*1000000),"") -> 6120.028 | J29: =IFERROR(J3*10000000/(J2*1000000),"") -> 6084.6556 | ... L29: =IFERROR(L3*10000000/(L2*1000000),"") -> 5838.0107
A30: Invested capital (NFA + NWC) | C30: =C14+C17 -> 23546 | D30: =D14+D17 -> 40354 | E30: =E14+E17 -> 49969 | F30: =F14+F17 -> 49676 | G30: =G14+G17 -> 46974 | H30: =H14+H17 -> 50986 | I30: =I14+I17 -> 59937 | J30: =J14+J17 -> 65294 | ... L30: =L14+L17 -> 86090
A31: NOPAT (EBIT at statutory tax) | C31: =C8*(1-'UTCL-Assumptions'!$C$4) -> 4361 | D31: =D8*(1-'UTCL-Assumptions'!$C$4) -> 4719 | E31: =E8*(1-'UTCL-Assumptions'!$C$4) -> 5255 | F31: =F8*(1-'UTCL-Assumptions'!$C$4) -> 6924 | G31: =G8*(1-'UTCL-Assumptions'!$C$4) -> 9319 | H31: =H8*(1-'UTCL-Assumptions'!$C$4) -> 9091 | I31: =I8*(1-'UTCL-Assumptions'!$C$4) -> 8018 | J31: =J8*(1-'UTCL-Assumptions'!$C$4) -> 10255 | ... L31: =L8*(1-'UTCL-Assumptions'!$C$4) -> 11761
A32: ROIC on opening invested capital | D32: =IFERROR(D31/C30,"") -> 0.20041621 | E32: =IFERROR(E31/D30,"") -> 0.13022253 | F32: =IFERROR(F31/E30,"") -> 0.13856591 | G32: =IFERROR(G31/F30,"") -> 0.18759562 | H32: =IFERROR(H31/G30,"") -> 0.19353259 | I32: =IFERROR(I31/H30,"") -> 0.15725886 | J32: =IFERROR(J31/I30,"") -> 0.17109632 | K32: =IFERROR(K31/J30,"") -> 0.14166692 | L32: =IFERROR(L31/K30,"") -> 0.14389537
A33: Effective tax rate as reported | C33: =IFERROR(C12/(C10+C11),"") -> 0.30402542 | D33: =IFERROR(D12/(D10+D11),"") -> 0.32434888 | E33: =IFERROR(E12/(E10+E11),"") -> 0.30927835 | F33: =IFERROR(F12/(F10+F11),"") -> -0.045210728 | G33: =IFERROR(G12/(G10+G11),"") -> 0.32345491 | H33: =IFERROR(H12/(H10+H11),"") -> 0.14795611 | I33: =IFERROR(I12/(I10+I11),"") -> 0.31809419 | J33: =IFERROR(J12/(J10+J11),"") -> 0.25880206 | ... L33: =IFERROR(L12/(L10+L11),"") -> 0.26149397
A34: Net debt (loans + leases - liquid inv) | C34: =C21+C22-C16 -> -2423 | D34: =D21+D22-D16 -> 12008 | E34: =E21+E22-E16 -> 17413 | F34: =F21+F22-F16 -> 13293 | G34: =G21+G22-G16 -> 4733 | H34: =H21+H22-H16 -> 4661 | I34: =I21+I22-I16 -> 3457 | J34: =J21+J22-J16 -> 1994 | ... L34: =L21+L22-L16 -> 15462
A36: Source: UltraTech Cement Ltd, Integrated and Sustainability Report 2025-26, Standalone Financial Highlights. Capital employed ties both ways: net worth plus loan funds plus leases plus deferred tax liabilities equals net fixed assets plus investments plus liquid investments plus net working capital, for every one of the ten years. The company's Operating Profit line equals EBITDA excluding other income, which is the definition used throughout this workbook and in the peer comparison.

Sheet UTCL-Entity Build
A1: Entity Build: standalone plus subsidiary holdings
A2: UltraTech Cement Ltd, FY2025-26. The operating business is valued standalone; subsidiaries are added as holdings.
A4: Step 1: standalone operating business, as reported
A5: Line item | B5: Unit | C5: FY2025-26 | E5: Source
A6: Revenue | B6: Rs cr | C6: 82,170 | E6: Ten year standalone financial highlights
A7: EBITDA (Operating Profit) | B7: Rs cr | C7: 15,439 | E7: Same table. Ties exactly to our uniform EBITDA definition.
A8: EBITDA margin | B8: Rs cr | C8: 18.8%
A9: Grey cement sales volume | B9: Rs cr | C9: 140.75 Mn.T
A10: Net fixed assets incl CWIP | B10: Rs cr | C10: 89,161
A11: Net worth | B11: Rs cr | C11: 74,663
A13: Step 2: subsidiary and other holdings, added at the bridge
A14: Holding | B14: Stake | C14: Carrying value | D14: Per UTCL share | E14: Basis
A15: The India Cements Ltd (LISTED) | B15: 74.99% | C15: 8970.17 | D15: =C15/'UTCL-Assumptions'!$B$5 -> 304.40376 | E15: 23,24,16,830 shares, or Rs 385.95 per India Cements share. Disclosed in the non-current investments note.
A16: Other investments in subsidiaries and associates | B16: various | C16: 3570.83 | D16: =C16/'UTCL-Assumptions'!$B$5 -> 121.17653 | E16: Total investments in subsidiaries, associates and others of Rs 12,541 cr less the India Cements carrying value.
A17: Liquid investments | B17: n/a | C17: 5018 | D17: =C17/'UTCL-Assumptions'!$B$5 -> 170.28641 | E17: Ten year table.
A19: Step 3: why UltraTech is NOT valued consolidated
A20: UltraTech does not publish a ten year consolidated history, and its FY2025-26 consolidated statements were not obtained from an authorised source. Consolidated figures exist only in broker research, which our data policy excludes. The standalone series is complete, audited and reconciles both ways in every one of the ten years, so it is the only basis on which a defensible historical analysis can be built. Subsidiaries are therefore added as holdings at carrying value rather than consolidated line by line.
A24: KNOWN INCONSISTENCY WITH THE AMBUJA MODEL, stated openly. UltraTech holds 74.99% of the listed India Cements and is valued STANDALONE with the stake added at book. Ambuja holds 50.05% of the listed ACC and is valued CONSOLIDATED. Two companies in the same structural position are treated differently, and the reason is data availability rather than principle. The irony is that UltraTech's stake is the MORE controlling of the two. Two consequences follow. First, marking India Cements to market instead of book would move the value by about Rs 79 per UltraTech share for every Rs 100 on the India Cements price. Second, if UltraTech consolidated statements are obtained, this tab is where the build up would be completed and the two models made consistent.
A30: Step 4: the equity bridge that results
A31: Enterprise value of standalone operations | C31: ='UTCL-FCFF valuation'!C9 -> 171426.72
A32: Add: liquid investments | C32: 5018
A33: Add: investments in subsidiaries and others | C33: 12541
A34: Less: loan funds | C34: -19617
A35: Less: lease liabilities | C35: -863
A36: Equity value | C36: =SUM(C31:C35) -> 168505.72
A37: Value per share | C37: =C36/'UTCL-Assumptions'!$B$5 -> 5718.261
A40: Step 5: the consolidated position, reconciled and quantified
A41: Line item | B41: Unit | C41: Standalone | D41: Consolidated | E41: Subsidiaries
A42: Revenue from operations | B42: Rs cr | C42: 82169.65 | D42: 88511.53 | E42: =D42-C42 -> 6341.88
A43: Other income | B43: Rs cr | C43: 376.43 | D43: 577.51 | E43: =D43-C43 -> 201.08
A44: Finance costs | B44: Rs cr | C44: 1630 | D44: 1871.71 | E44: =D44-C44 -> 241.71
A45: Depreciation and amortisation | B45: Rs cr | C45: 4055.08 | D45: 4644.46 | E45: =D45-C45 -> 589.38
A46: Profit before exceptional items and tax | B46: Rs cr | C46: 10130.58 | D46: 11081.57 | E46: =D46-C46 -> 950.99
A47: EBITDA (uniform definition) | C47: =C46+C44+C45-C43 -> 15439.23 | D47: =D46+D44+D45-D43 -> 17020.23 | E47: =E46+E44+E45-E43 -> 1581
A48: EBITDA margin | C48: =C47/C42 -> 0.18789456 | D48: =D47/D42 -> 0.19229393 | E48: =E47/E42 -> 0.24929516
A49: Standalone share of group | C49: =C42/D42 -> 0.92834967 | D49: =C47/D47 -> 0.90711054 | E49: revenue / EBITDA
A51: Consolidated goodwill | C51: 7909.05
A52: Consolidated non-controlling interest | C52: 4088.9
A53: Consolidated borrowings and leases | C53: 23755.09
A54: Standalone borrowings and leases | C54: 20480
...

Sheet UTCL-Normalize
A1: Normalisation and reclassification
A3: Item | B3: Unit | C3: As reported | D3: Normalised | E3: Basis and note reference
A4: Capital work in progress | B4: Rs cr | C4: 7871.47 | D4: 0 | E4: Note 02. Excluded from the capital intensity measure because CWIP earns no revenue yet; scaling total fixed assets to current sales would penalise the company for capacity already paid for. Correcting this raised value about 14%.
A5: Exceptional items | B5: Rs cr | C5: 103.79 | D5: 0 | E5: Ten year table. Provision for impairment of investment Rs 23.03 cr plus statutory impact of new labour codes Rs 80.76 cr. Removed from earnings.
A6: Other income | B6: Rs cr | C6: 376.43 | D6: 0 | E6: Excluded from EBITDA under our uniform definition, so cash and investments are non-operating and added back once at the bridge.
A7: Tax rate | B7: % | C7: 0.261 | D7: 0.25168 | E7: Reported effective rate of 26.1% cross checked against the s.115BAA statutory rate of 25.168%. Materially in line, so no migration path is modelled. Statutory used throughout.
A8: India Cements holding | B8: Rs cr | C8: 8970.17 | D8: 8970.17 | E8: Non-current investments note. Carried at BOOK. India Cements is LISTED, so asset consistency would prefer market value. Flagged as an open item; a price cell exists on the Assumptions sheet.
A9: Unlevered beta | B9: x | C9: 0.86 | D9: 0.9 | E9: Damodaran Global January 2026. CASH CORRECTED figure adopted because cash is added back separately at the bridge; the raw 0.86 would count cash twice.

Sheet UTCL-Common Size
A1: Common Size Statements: UltraTech Cement (standalone)
A2: Every figure recomputed from the ten year table on Source-Data. Nothing downloaded.
A4: Line item | B4: 2016-17 | C4: 2017-18 | D4: 2018-19 R | E4: 2019-20 | F4: 2020-21 | G4: 2021-22 | H4: 2022-23 R | I4: 2023-24 | J4: 2024-25 | K4: 2025-26
A5: Income statement, percent of revenue
A6: Operating expenses | B6: ='UTCL-Source Data'!C4/'UTCL-Source Data'!C3 -> 0.79201373 | C6: ='UTCL-Source Data'!D4/'UTCL-Source Data'!D3 -> 0.79961169 | D6: ='UTCL-Source Data'!E4/'UTCL-Source Data'!E3 -> 0.82302058 | E6: ='UTCL-Source Data'!F4/'UTCL-Source Data'!F3 -> 0.78715344 | F6: ='UTCL-Source Data'!G4/'UTCL-Source Data'!G3 -> 0.74613319 | G6: ='UTCL-Source Data'!H4/'UTCL-Source Data'!H3 -> 0.78414227 | H6: ='UTCL-Source Data'!I4/'UTCL-Source Data'!I3 -> 0.83204599 | I6: ='UTCL-Source Data'!J4/'UTCL-Source Data'!J3 -> 0.81614487 | ... K6: ='UTCL-Source Data'!L4/'UTCL-Source Data'!L3 -> 0.81209687
A7: Operating profit (EBITDA) | B7: ='UTCL-Source Data'!C5/'UTCL-Source Data'!C3 -> 0.20798627 | C7: ='UTCL-Source Data'!D5/'UTCL-Source Data'!D3 -> 0.20038831 | D7: ='UTCL-Source Data'!E5/'UTCL-Source Data'!E3 -> 0.17697942 | E7: ='UTCL-Source Data'!F5/'UTCL-Source Data'!F3 -> 0.21284656 | F7: ='UTCL-Source Data'!G5/'UTCL-Source Data'!G3 -> 0.25388997 | G7: ='UTCL-Source Data'!H5/'UTCL-Source Data'!H3 -> 0.21585773 | H7: ='UTCL-Source Data'!I5/'UTCL-Source Data'!I3 -> 0.16797034 | I7: ='UTCL-Source Data'!J5/'UTCL-Source Data'!J3 -> 0.18385513 | ... K7: ='UTCL-Source Data'!L5/'UTCL-Source Data'!L3 -> 0.18789096
A8: Other income | B8: ='UTCL-Source Data'!C6/'UTCL-Source Data'!C3 -> 0.027625466 | C8: ='UTCL-Source Data'!D6/'UTCL-Source Data'!D3 -> 0.020437359 | D8: ='UTCL-Source Data'!E6/'UTCL-Source Data'!E3 -> 0.012425311 | E8: ='UTCL-Source Data'!F6/'UTCL-Source Data'!F3 -> 0.017884819 | F8: ='UTCL-Source Data'!G6/'UTCL-Source Data'!G3 -> 0.018268964 | G8: ='UTCL-Source Data'!H6/'UTCL-Source Data'!H3 -> 0.012079822 | H8: ='UTCL-Source Data'!I6/'UTCL-Source Data'!I3 -> 0.0082466483 | I8: ='UTCL-Source Data'!J6/'UTCL-Source Data'!J3 -> 0.0096443816 | ... K8: ='UTCL-Source Data'!L6/'UTCL-Source Data'!L3 -> 0.0045758793
A9: Depreciation and amortisation | B9: ='UTCL-Source Data'!C7/'UTCL-Source Data'!C3 -> 0.053074379 | C9: ='UTCL-Source Data'!D7/'UTCL-Source Data'!D3 -> 0.060085837 | D9: ='UTCL-Source Data'!E7/'UTCL-Source Data'!E3 -> 0.058026451 | E9: ='UTCL-Source Data'!F7/'UTCL-Source Data'!F3 -> 0.06039509 | F9: ='UTCL-Source Data'!G7/'UTCL-Source Data'!G3 -> 0.056358248 | G9: ='UTCL-Source Data'!H7/'UTCL-Source Data'!H3 -> 0.048496931 | H9: ='UTCL-Source Data'!I7/'UTCL-Source Data'!I3 -> 0.04528308 | I9: ='UTCL-Source Data'!J7/'UTCL-Source Data'!J3 -> 0.044099008 | ... K9: ='UTCL-Source Data'!L7/'UTCL-Source Data'!L3 -> 0.049348911
A10: EBIT | B10: ='UTCL-Source Data'!C8/'UTCL-Source Data'!C3 -> 0.18253736 | C10: ='UTCL-Source Data'!D8/'UTCL-Source Data'!D3 -> 0.16073983 | D10: ='UTCL-Source Data'!E8/'UTCL-Source Data'!E3 -> 0.13137828 | E10: ='UTCL-Source Data'!F8/'UTCL-Source Data'!F3 -> 0.17033629 | F10: ='UTCL-Source Data'!G8/'UTCL-Source Data'!G3 -> 0.21577753 | G10: ='UTCL-Source Data'!H8/'UTCL-Source Data'!H3 -> 0.17944062 | H10: ='UTCL-Source Data'!I8/'UTCL-Source Data'!I3 -> 0.13093391 | I10: ='UTCL-Source Data'!J8/'UTCL-Source Data'!J3 -> 0.1494005 | ... K10: ='UTCL-Source Data'!L8/'UTCL-Source Data'!L3 -> 0.1431301
A11: Interest | B11: ='UTCL-Source Data'!C9/'UTCL-Source Data'!C3 -> 0.023900213 | C11: ='UTCL-Source Data'!D9/'UTCL-Source Data'!D3 -> 0.040568159 | D11: ='UTCL-Source Data'!E9/'UTCL-Source Data'!E3 -> 0.04120103 | E11: ='UTCL-Source Data'!F9/'UTCL-Source Data'!F3 -> 0.04191985 | F11: ='UTCL-Source Data'!G9/'UTCL-Source Data'!G3 -> 0.029151616 | G11: ='UTCL-Source Data'!H9/'UTCL-Source Data'!H3 -> 0.01575114 | H11: ='UTCL-Source Data'!I9/'UTCL-Source Data'!I3 -> 0.012345477 | I11: ='UTCL-Source Data'!J9/'UTCL-Source Data'!J3 -> 0.012630935 | ... K11: ='UTCL-Source Data'!L9/'UTCL-Source Data'!L3 -> 0.019836923
A12: Profit before tax | B12: ='UTCL-Source Data'!C10/'UTCL-Source Data'!C3 -> 0.15863714 | C12: ='UTCL-Source Data'!D10/'UTCL-Source Data'!D3 -> 0.12017167 | D12: ='UTCL-Source Data'!E10/'UTCL-Source Data'!E3 -> 0.090152254 | E12: ='UTCL-Source Data'!F10/'UTCL-Source Data'!F3 -> 0.12841644 | F12: ='UTCL-Source Data'!G10/'UTCL-Source Data'!G3 -> 0.18662591 | G12: ='UTCL-Source Data'!H10/'UTCL-Source Data'!H3 -> 0.16368948 | H12: ='UTCL-Source Data'!I10/'UTCL-Source Data'!I3 -> 0.11858844 | I12: ='UTCL-Source Data'!J10/'UTCL-Source Data'!J3 -> 0.13676957 | ... K12: ='UTCL-Source Data'!L10/'UTCL-Source Data'!L3 -> 0.12329317
A13: Tax expense | B13: ='UTCL-Source Data'!C12/'UTCL-Source Data'!C3 -> 0.048051568 | C13: ='UTCL-Source Data'!D12/'UTCL-Source Data'!D3 -> 0.036480687 | D13: ='UTCL-Source Data'!E12/'UTCL-Source Data'!E3 -> 0.027000675 | E13: ='UTCL-Source Data'!F12/'UTCL-Source Data'!F3 -> -0.0058058009 | F13: ='UTCL-Source Data'!G12/'UTCL-Source Data'!G3 -> 0.059136797 | G13: ='UTCL-Source Data'!H12/'UTCL-Source Data'!H3 -> 0.024218858 | H13: ='UTCL-Source Data'!I12/'UTCL-Source Data'!I3 -> 0.037722292 | I13: ='UTCL-Source Data'!J12/'UTCL-Source Data'!J3 -> 0.03512478 | ... K13: ='UTCL-Source Data'!L12/'UTCL-Source Data'!L3 -> 0.031909456
A14: Net profit | B14: ='UTCL-Source Data'!C13/'UTCL-Source Data'!C3 -> 0.10999958 | C14: ='UTCL-Source Data'!D13/'UTCL-Source Data'!D3 -> 0.075992915 | D14: ='UTCL-Source Data'!E13/'UTCL-Source Data'!E3 -> 0.060301508 | E14: ='UTCL-Source Data'!F13/'UTCL-Source Data'!F3 -> 0.13422224 | F14: ='UTCL-Source Data'!G13/'UTCL-Source Data'!G3 -> 0.12369177 | G14: ='UTCL-Source Data'!H13/'UTCL-Source Data'!H3 -> 0.13949036 | H14: ='UTCL-Source Data'!I13/'UTCL-Source Data'!I3 -> 0.080849813 | I14: ='UTCL-Source Data'!J13/'UTCL-Source Data'!J3 -> 0.10059585 | ... K14: ='UTCL-Source Data'!L13/'UTCL-Source Data'!L3 -> 0.090118048
A16: Capital employed, percent of total
A17: Net fixed assets incl ROU, CWIP | B17: ='UTCL-Source Data'!C14/'UTCL-Source Data'!C24 -> 0.7400091 | C17: ='UTCL-Source Data'!D14/'UTCL-Source Data'!D24 -> 0.87671174 | D17: ='UTCL-Source Data'!E14/'UTCL-Source Data'!E24 -> 0.83756611 | E17: ='UTCL-Source Data'!F14/'UTCL-Source Data'!F24 -> 0.80402288 | F17: ='UTCL-Source Data'!G14/'UTCL-Source Data'!G24 -> 0.7347427 | G17: ='UTCL-Source Data'!H14/'UTCL-Source Data'!H24 -> 0.80587046 | H17: ='UTCL-Source Data'!I14/'UTCL-Source Data'!I24 -> 0.90929666 | I17: ='UTCL-Source Data'!J14/'UTCL-Source Data'!J24 -> 0.93072681 | ... K17: ='UTCL-Source Data'!L14/'UTCL-Source Data'!L24 -> 0.86022055
A18: Investments in subsidiaries and others | B18: ='UTCL-Source Data'!C15/'UTCL-Source Data'!C24 -> 0.022636929 | C18: ='UTCL-Source Data'!D15/'UTCL-Source Data'!D24 -> 0.016144635 | D18: ='UTCL-Source Data'!E15/'UTCL-Source Data'!E24 -> 0.10118112 | E18: ='UTCL-Source Data'!F15/'UTCL-Source Data'!F24 -> 0.097322415 | F18: ='UTCL-Source Data'!G15/'UTCL-Source Data'!G24 -> 0.094638639 | G18: ='UTCL-Source Data'!H15/'UTCL-Source Data'!H24 -> 0.12526809 | H18: ='UTCL-Source Data'!I15/'UTCL-Source Data'!I24 -> 0.045942712 | I18: ='UTCL-Source Data'!J15/'UTCL-Source Data'!J24 -> 0.029799681 | ... K18: ='UTCL-Source Data'!L15/'UTCL-Source Data'!L24 -> 0.1209949
A19: Liquid investments | B19: ='UTCL-Source Data'!C16/'UTCL-Source Data'!C24 -> 0.26287362 | C19: ='UTCL-Source Data'!D16/'UTCL-Source Data'!D24 -> 0.11634456 | D19: ='UTCL-Source Data'!E16/'UTCL-Source Data'!E24 -> 0.054476944 | E19: ='UTCL-Source Data'!F16/'UTCL-Source Data'!F24 -> 0.095567687 | F19: ='UTCL-Source Data'!G16/'UTCL-Source Data'!G24 -> 0.20306193 | G19: ='UTCL-Source Data'!H16/'UTCL-Source Data'!H24 -> 0.093679147 | H19: ='UTCL-Source Data'!I16/'UTCL-Source Data'!I24 -> 0.09004022 | I19: ='UTCL-Source Data'!J16/'UTCL-Source Data'!J24 -> 0.094135326 | ... K19: ='UTCL-Source Data'!L16/'UTCL-Source Data'!L24 -> 0.048413395
A20: Net working capital | B20: ='UTCL-Source Data'!C17/'UTCL-Source Data'!C24 -> -0.025519648 | C20: ='UTCL-Source Data'!D17/'UTCL-Source Data'!D24 -> -0.0092009373 | D20: ='UTCL-Source Data'!E17/'UTCL-Source Data'!E24 -> 0.0067758233 | E20: ='UTCL-Source Data'!F17/'UTCL-Source Data'!F24 -> 0.0030870215 | F20: ='UTCL-Source Data'!G17/'UTCL-Source Data'!G24 -> -0.032443262 | G20: ='UTCL-Source Data'!H17/'UTCL-Source Data'!H24 -> -0.024787058 | H20: ='UTCL-Source Data'!I17/'UTCL-Source Data'!I24 -> -0.045265176 | I20: ='UTCL-Source Data'!J17/'UTCL-Source Data'!J24 -> -0.054661819 | ... K20: ='UTCL-Source Data'!L17/'UTCL-Source Data'!L24 -> -0.029628844
A21: Net worth | B21: ='UTCL-Source Data'!C20/'UTCL-Source Data'!C24 -> 0.7264755 | C21: ='UTCL-Source Data'!D20/'UTCL-Source Data'!D24 -> 0.55728013 | D21: ='UTCL-Source Data'!E20/'UTCL-Source Data'!E24 -> 0.5626299 | E21: ='UTCL-Source Data'!F20/'UTCL-Source Data'!F24 -> 0.62221356 | F21: ='UTCL-Source Data'!G20/'UTCL-Source Data'!G24 -> 0.64816255 | G21: ='UTCL-Source Data'!H20/'UTCL-Source Data'!H24 -> 0.75481034 | H21: ='UTCL-Source Data'!I20/'UTCL-Source Data'!I24 -> 0.76991163 | I21: ='UTCL-Source Data'!J20/'UTCL-Source Data'!J24 -> 0.79289155 | ... K21: ='UTCL-Source Data'!L20/'UTCL-Source Data'!L24 -> 0.72034462
A22: Loan funds | B22: ='UTCL-Source Data'!C21/'UTCL-Source Data'!C24 -> 0.18934911 | C22: ='UTCL-Source Data'!D21/'UTCL-Source Data'!D24 -> 0.37448675 | D22: ='UTCL-Source Data'!E21/'UTCL-Source Data'!E24 -> 0.34870989 | E22: ='UTCL-Source Data'!F21/'UTCL-Source Data'!F24 -> 0.29703646 | F22: ='UTCL-Source Data'!G21/'UTCL-Source Data'!G24 -> 0.25893311 | G22: ='UTCL-Source Data'!H21/'UTCL-Source Data'!H24 -> 0.15152583 | H22: ='UTCL-Source Data'!I21/'UTCL-Source Data'!I24 -> 0.12613704 | I22: ='UTCL-Source Data'!J21/'UTCL-Source Data'!J24 -> 0.10850519 | ... K22: ='UTCL-Source Data'!L21/'UTCL-Source Data'!L24 -> 0.18926377
A23: Lease liabilities | B23: ='UTCL-Source Data'!C22/'UTCL-Source Data'!C24 -> 0 | C23: ='UTCL-Source Data'!D22/'UTCL-Source Data'!D24 -> 0 | D23: ='UTCL-Source Data'!E22/'UTCL-Source Data'!E24 -> 0 | E23: ='UTCL-Source Data'!F22/'UTCL-Source Data'!F24 -> 0.014509001 | F23: ='UTCL-Source Data'!G22/'UTCL-Source Data'!G24 -> 0.014891009 | G23: ='UTCL-Source Data'!H22/'UTCL-Source Data'!H24 -> 0.013557816 | H23: ='UTCL-Source Data'!I22/'UTCL-Source Data'!I24 -> 0.013738125 | I23: ='UTCL-Source Data'!J22/'UTCL-Source Data'!J24 -> 0.012384109 | ... K23: ='UTCL-Source Data'!L22/'UTCL-Source Data'!L24 -> 0.0083261778
A24: Deferred tax liabilities | B24: ='UTCL-Source Data'!C23/'UTCL-Source Data'!C24 -> 0.084175391 | C24: ='UTCL-Source Data'!D23/'UTCL-Source Data'!D24 -> 0.068233119 | D24: ='UTCL-Source Data'!E23/'UTCL-Source Data'!E24 -> 0.088660212 | E24: ='UTCL-Source Data'!F23/'UTCL-Source Data'!F24 -> 0.066240983 | F24: ='UTCL-Source Data'!G23/'UTCL-Source Data'!G24 -> 0.078028287 | G24: ='UTCL-Source Data'!H23/'UTCL-Source Data'!H24 -> 0.080121331 | H24: ='UTCL-Source Data'!I23/'UTCL-Source Data'!I24 -> 0.090213208 | I24: ='UTCL-Source Data'!J23/'UTCL-Source Data'!J24 -> 0.08620574 | ... K24: ='UTCL-Source Data'!L23/'UTCL-Source Data'!L24 -> 0.082065432
A26: What to read here. The operating profit line is the story: 20.8% of revenue in FY2016-17, peaking at 25.4% in FY2020-21, and 18.8% in FY2025-26. Margin has compressed by roughly 650 basis points from the peak even as revenue more than tripled. On the capital side, net fixed assets have stayed near 86% of capital employed while net worth has risen from 73% to 72% and loan funds have swung from 19% to 26% and back. The company has grown by adding assets rather than by improving what it earns on them, which is the same conclusion the ROIC series reaches from the other direction.

Sheet UTCL-Ratios
A1: Ratio Analysis: UltraTech Cement (standalone)
A2: Computed from Source-Data. Returns use the statutory tax rate, never the reported effective rate.
A4: Ratio | B4: 2016-17 | C4: 2017-18 | D4: 2018-19 R | E4: 2019-20 | F4: 2020-21 | G4: 2021-22 | H4: 2022-23 R | I4: 2023-24 | J4: 2024-25 | K4: 2025-26
A5: Profitability
A6: EBITDA margin | B6: ='UTCL-Source Data'!C5/'UTCL-Source Data'!C3 -> 0.20798627 | C6: ='UTCL-Source Data'!D5/'UTCL-Source Data'!D3 -> 0.20038831 | D6: ='UTCL-Source Data'!E5/'UTCL-Source Data'!E3 -> 0.17697942 | E6: ='UTCL-Source Data'!F5/'UTCL-Source Data'!F3 -> 0.21284656 | F6: ='UTCL-Source Data'!G5/'UTCL-Source Data'!G3 -> 0.25388997 | G6: ='UTCL-Source Data'!H5/'UTCL-Source Data'!H3 -> 0.21585773 | H6: ='UTCL-Source Data'!I5/'UTCL-Source Data'!I3 -> 0.16797034 | I6: ='UTCL-Source Data'!J5/'UTCL-Source Data'!J3 -> 0.18385513 | ... K6: ='UTCL-Source Data'!L5/'UTCL-Source Data'!L3 -> 0.18789096
A7: EBIT margin | B7: ='UTCL-Source Data'!C8/'UTCL-Source Data'!C3 -> 0.18253736 | C7: ='UTCL-Source Data'!D8/'UTCL-Source Data'!D3 -> 0.16073983 | D7: ='UTCL-Source Data'!E8/'UTCL-Source Data'!E3 -> 0.13137828 | E7: ='UTCL-Source Data'!F8/'UTCL-Source Data'!F3 -> 0.17033629 | F7: ='UTCL-Source Data'!G8/'UTCL-Source Data'!G3 -> 0.21577753 | G7: ='UTCL-Source Data'!H8/'UTCL-Source Data'!H3 -> 0.17944062 | H7: ='UTCL-Source Data'!I8/'UTCL-Source Data'!I3 -> 0.13093391 | I7: ='UTCL-Source Data'!J8/'UTCL-Source Data'!J3 -> 0.1494005 | ... K7: ='UTCL-Source Data'!L8/'UTCL-Source Data'!L3 -> 0.1431301
A8: Net profit margin | B8: ='UTCL-Source Data'!C13/'UTCL-Source Data'!C3 -> 0.10999958 | C8: ='UTCL-Source Data'!D13/'UTCL-Source Data'!D3 -> 0.075992915 | D8: ='UTCL-Source Data'!E13/'UTCL-Source Data'!E3 -> 0.060301508 | E8: ='UTCL-Source Data'!F13/'UTCL-Source Data'!F3 -> 0.13422224 | F8: ='UTCL-Source Data'!G13/'UTCL-Source Data'!G3 -> 0.12369177 | G8: ='UTCL-Source Data'!H13/'UTCL-Source Data'!H3 -> 0.13949036 | H8: ='UTCL-Source Data'!I13/'UTCL-Source Data'!I3 -> 0.080849813 | I8: ='UTCL-Source Data'!J13/'UTCL-Source Data'!J3 -> 0.10059585 | ... K8: ='UTCL-Source Data'!L13/'UTCL-Source Data'!L3 -> 0.090118048
A9: Return on equity (reported) | B9: ='UTCL-Source Data'!C13/'UTCL-Source Data'!C20 -> 0.10976985 | C9: ='UTCL-Source Data'!D13/'UTCL-Source Data'!D20 -> 0.08606257 | D9: ='UTCL-Source Data'!E13/'UTCL-Source Data'!E20 -> 0.072438958 | E9: ='UTCL-Source Data'!F13/'UTCL-Source Data'!F20 -> 0.14246919 | F9: ='UTCL-Source Data'!G13/'UTCL-Source Data'!G20 -> 0.123221 | G9: ='UTCL-Source Data'!H13/'UTCL-Source Data'!H20 -> 0.14343123 | H9: ='UTCL-Source Data'!I13/'UTCL-Source Data'!I20 -> 0.092701468 | I9: ='UTCL-Source Data'!J13/'UTCL-Source Data'!J20 -> 0.11684576 | ... K9: ='UTCL-Source Data'!L13/'UTCL-Source Data'!L20 -> 0.099178978
A10: Return on capital employed (EBIT) | B10: ='UTCL-Source Data'!C8/'UTCL-Source Data'!C24 -> 0.13233197 | C10: ='UTCL-Source Data'!D8/'UTCL-Source Data'!D24 -> 0.10144678 | D10: ='UTCL-Source Data'!E8/'UTCL-Source Data'!E24 -> 0.08879539 | E10: ='UTCL-Source Data'!F8/'UTCL-Source Data'!F24 -> 0.11249756 | F10: ='UTCL-Source Data'!G8/'UTCL-Source Data'!G24 -> 0.13932662 | G10: ='UTCL-Source Data'!H8/'UTCL-Source Data'!H24 -> 0.13927018 | H10: ='UTCL-Source Data'!I8/'UTCL-Source Data'!I24 -> 0.11558477 | I10: ='UTCL-Source Data'!J8/'UTCL-Source Data'!J24 -> 0.13759375 | ... K10: ='UTCL-Source Data'!L8/'UTCL-Source Data'!L24 -> 0.1134695
A11: ROIC on opening invested capital | C11: ='UTCL-Source Data'!D8*(1-'UTCL-Assumptions'!$B$4)/('UTCL-Source Data'!C14+'UTCL-Source Data'!C17) -> 0.14997546 | D11: ='UTCL-Source Data'!E8*(1-'UTCL-Assumptions'!$B$4)/('UTCL-Source Data'!D14+'UTCL-Source Data'!D17) -> 0.097448124 | E11: ='UTCL-Source Data'!F8*(1-'UTCL-Assumptions'!$B$4)/('UTCL-Source Data'!E14+'UTCL-Source Data'!E17) -> 0.10369164 | F11: ='UTCL-Source Data'!G8*(1-'UTCL-Assumptions'!$B$4)/('UTCL-Source Data'!F14+'UTCL-Source Data'!F17) -> 0.14038155 | G11: ='UTCL-Source Data'!H8*(1-'UTCL-Assumptions'!$B$4)/('UTCL-Source Data'!G14+'UTCL-Source Data'!G17) -> 0.14482431 | H11: ='UTCL-Source Data'!I8*(1-'UTCL-Assumptions'!$B$4)/('UTCL-Source Data'!H14+'UTCL-Source Data'!H17) -> 0.11767995 | I11: ='UTCL-Source Data'!J8*(1-'UTCL-Assumptions'!$B$4)/('UTCL-Source Data'!I14+'UTCL-Source Data'!I17) -> 0.1280348 | J11: ='UTCL-Source Data'!K8*(1-'UTCL-Assumptions'!$B$4)/('UTCL-Source Data'!J14+'UTCL-Source Data'!J17) -> 0.10601219 | K11: ='UTCL-Source Data'!L8*(1-'UTCL-Assumptions'!$B$4)/('UTCL-Source Data'!K14+'UTCL-Source Data'!K17) -> 0.10767978
A13: Per tonne economics
A14: Realisation per tonne (Rs) | B14: ='UTCL-Source Data'!C3*10/'UTCL-Source Data'!C2 -> 4888.6843 | C14: ='UTCL-Source Data'!D3*10/'UTCL-Source Data'!D2 -> 4948.2555 | D14: ='UTCL-Source Data'!E3*10/'UTCL-Source Data'!E2 -> 4951.5969 | E14: ='UTCL-Source Data'!F3*10/'UTCL-Source Data'!F2 -> 5247.7408 | F14: ='UTCL-Source Data'!G3*10/'UTCL-Source Data'!G2 -> 5315.4462 | G14: ='UTCL-Source Data'!H3*10/'UTCL-Source Data'!H2 -> 5755.8509 | H14: ='UTCL-Source Data'!I3*10/'UTCL-Source Data'!I2 -> 6120.028 | I14: ='UTCL-Source Data'!J3*10/'UTCL-Source Data'!J2 -> 6084.6556 | ... K14: ='UTCL-Source Data'!L3*10/'UTCL-Source Data'!L2 -> 5838.0107
A15: EBITDA per tonne (Rs) | B15: ='UTCL-Source Data'!C5*10/'UTCL-Source Data'!C2 -> 1016.7792 | C15: ='UTCL-Source Data'!D5*10/'UTCL-Source Data'!D2 -> 991.57256 | D15: ='UTCL-Source Data'!E5*10/'UTCL-Source Data'!E2 -> 876.33077 | E15: ='UTCL-Source Data'!F5*10/'UTCL-Source Data'!F2 -> 1116.9636 | F15: ='UTCL-Source Data'!G5*10/'UTCL-Source Data'!G2 -> 1349.5385 | G15: ='UTCL-Source Data'!H5*10/'UTCL-Source Data'!H2 -> 1242.4449 | H15: ='UTCL-Source Data'!I5*10/'UTCL-Source Data'!I2 -> 1027.9832 | I15: ='UTCL-Source Data'!J5*10/'UTCL-Source Data'!J2 -> 1118.6952 | ... K15: ='UTCL-Source Data'!L5*10/'UTCL-Source Data'!L2 -> 1096.9094
A16: Operating cost per tonne (Rs) | B16: ='UTCL-Source Data'!C4*10/'UTCL-Source Data'!C2 -> 3871.9051 | C16: ='UTCL-Source Data'!D4*10/'UTCL-Source Data'!D2 -> 3956.683 | D16: ='UTCL-Source Data'!E4*10/'UTCL-Source Data'!E2 -> 4075.2662 | E16: ='UTCL-Source Data'!F4*10/'UTCL-Source Data'!F2 -> 4130.7772 | F16: ='UTCL-Source Data'!G4*10/'UTCL-Source Data'!G2 -> 3966.0308 | G16: ='UTCL-Source Data'!H4*10/'UTCL-Source Data'!H2 -> 4513.406 | H16: ='UTCL-Source Data'!I4*10/'UTCL-Source Data'!I2 -> 5092.1447 | I16: ='UTCL-Source Data'!J4*10/'UTCL-Source Data'!J2 -> 4965.9605 | ... K16: ='UTCL-Source Data'!L4*10/'UTCL-Source Data'!L2 -> 4741.0302
A17: Sales volume (Mn.T) | B17: ='UTCL-Source Data'!C2 -> 48.87 | C17: ='UTCL-Source Data'!D2 -> 59.33 | D17: ='UTCL-Source Data'!E2 -> 80.78 | E17: ='UTCL-Source Data'!F2 -> 77.46 | F17: ='UTCL-Source Data'!G2 -> 81.25 | G17: ='UTCL-Source Data'!H2 -> 88.02 | H17: ='UTCL-Source Data'!I2 -> 100.06 | I17: ='UTCL-Source Data'!J2 -> 112.81 | ... K17: ='UTCL-Source Data'!L2 -> 140.75
A19: Efficiency
A20: Revenue to net fixed assets | B20: ='UTCL-Source Data'!C3/'UTCL-Source Data'!C14 -> 0.97966129 | C20: ='UTCL-Source Data'!D3/'UTCL-Source Data'!D14 -> 0.71987642 | D20: ='UTCL-Source Data'!E3/'UTCL-Source Data'!E14 -> 0.80695207 | E20: ='UTCL-Source Data'!F3/'UTCL-Source Data'!F14 -> 0.82142424 | F20: ='UTCL-Source Data'!G3/'UTCL-Source Data'!G14 -> 0.87880514 | G20: ='UTCL-Source Data'!H3/'UTCL-Source Data'!H14 -> 0.96310167 | H20: ='UTCL-Source Data'!I3/'UTCL-Source Data'!I14 -> 0.9708293 | I20: ='UTCL-Source Data'!J3/'UTCL-Source Data'!J14 -> 0.98951966 | ... K20: ='UTCL-Source Data'!L3/'UTCL-Source Data'!L14 -> 0.92159128
A21: Net working capital, percent of revenue | B21: ='UTCL-Source Data'!C17/'UTCL-Source Data'!C3 -> -0.03520154 | C21: ='UTCL-Source Data'!D17/'UTCL-Source Data'!D3 -> -0.01457865 | D21: ='UTCL-Source Data'!E17/'UTCL-Source Data'!E3 -> 0.010025251 | E21: ='UTCL-Source Data'!F17/'UTCL-Source Data'!F3 -> 0.0046741617 | F21: ='UTCL-Source Data'!G17/'UTCL-Source Data'!G3 -> -0.050245439 | G21: ='UTCL-Source Data'!H17/'UTCL-Source Data'!H3 -> -0.031936522 | H21: ='UTCL-Source Data'!I17/'UTCL-Source Data'!I3 -> -0.051276189 | I21: ='UTCL-Source Data'!J17/'UTCL-Source Data'!J3 -> -0.059352282 | ... K21: ='UTCL-Source Data'!L17/'UTCL-Source Data'!L3 -> -0.037373737
A22: Capital employed per tonne (Rs) | B22: ='UTCL-Source Data'!C24*10/'UTCL-Source Data'!C2 -> 6743.4009 | C22: ='UTCL-Source Data'!D24*10/'UTCL-Source Data'!D2 -> 7840.3843 | D22: ='UTCL-Source Data'!E24*10/'UTCL-Source Data'!E2 -> 7326.1946 | E22: ='UTCL-Source Data'!F24*10/'UTCL-Source Data'!F2 -> 7945.7785 | F22: ='UTCL-Source Data'!G24*10/'UTCL-Source Data'!G2 -> 8232.1231 | G22: ='UTCL-Source Data'!H24*10/'UTCL-Source Data'!H2 -> 7416.0418 | H22: ='UTCL-Source Data'!I24*10/'UTCL-Source Data'!I2 -> 6932.7404 | I22: ='UTCL-Source Data'!J24*10/'UTCL-Source Data'!J2 -> 6606.7724 | ... K22: ='UTCL-Source Data'!L24*10/'UTCL-Source Data'!L2 -> 7364.0497
A24: Leverage and coverage
A25: Debt to equity | B25: =('UTCL-Source Data'!C21+'UTCL-Source Data'!C22)/'UTCL-Source Data'!C20 -> 0.26064074 | C25: =('UTCL-Source Data'!D21+'UTCL-Source Data'!D22)/'UTCL-Source Data'!D20 -> 0.67199012 | D25: =('UTCL-Source Data'!E21+'UTCL-Source Data'!E22)/'UTCL-Source Data'!E20 -> 0.61978557 | E25: =('UTCL-Source Data'!F21+'UTCL-Source Data'!F22)/'UTCL-Source Data'!F20 -> 0.50070503 | F25: =('UTCL-Source Data'!G21+'UTCL-Source Data'!G22)/'UTCL-Source Data'!G20 -> 0.42246211 | G25: =('UTCL-Source Data'!H21+'UTCL-Source Data'!H22)/'UTCL-Source Data'!H20 -> 0.21870877 | H25: =('UTCL-Source Data'!I21+'UTCL-Source Data'!I22)/'UTCL-Source Data'!I20 -> 0.1816769 | I25: =('UTCL-Source Data'!J21+'UTCL-Source Data'!J22)/'UTCL-Source Data'!J20 -> 0.15246637 | ... K25: =('UTCL-Source Data'!L21+'UTCL-Source Data'!L22)/'UTCL-Source Data'!L20 -> 0.27429918
A26: Net debt to EBITDA | B26: =('UTCL-Source Data'!C21+'UTCL-Source Data'!C22-'UTCL-Source Data'!C16)/'UTCL-Source Data'!C5 -> -0.48762326 | C26: =('UTCL-Source Data'!D21+'UTCL-Source Data'!D22-'UTCL-Source Data'!D16)/'UTCL-Source Data'!D5 -> 2.0411355 | D26: =('UTCL-Source Data'!E21+'UTCL-Source Data'!E22-'UTCL-Source Data'!E16)/'UTCL-Source Data'!E5 -> 2.4598107 | E26: =('UTCL-Source Data'!F21+'UTCL-Source Data'!F22-'UTCL-Source Data'!F16)/'UTCL-Source Data'!F5 -> 1.5364078 | F26: =('UTCL-Source Data'!G21+'UTCL-Source Data'!G22-'UTCL-Source Data'!G16)/'UTCL-Source Data'!G5 -> 0.43164615 | G26: =('UTCL-Source Data'!H21+'UTCL-Source Data'!H22-'UTCL-Source Data'!H16)/'UTCL-Source Data'!H5 -> 0.42620702 | H26: =('UTCL-Source Data'!I21+'UTCL-Source Data'!I22-'UTCL-Source Data'!I16)/'UTCL-Source Data'!I5 -> 0.33608789 | I26: =('UTCL-Source Data'!J21+'UTCL-Source Data'!J22-'UTCL-Source Data'!J16)/'UTCL-Source Data'!J5 -> 0.15800317 | ... K26: =('UTCL-Source Data'!L21+'UTCL-Source Data'!L22-'UTCL-Source Data'!L16)/'UTCL-Source Data'!L5 -> 1.0014897
A27: Interest coverage (EBIT / interest) | B27: ='UTCL-Source Data'!C8/'UTCL-Source Data'!C9 -> 7.6374781 | C27: ='UTCL-Source Data'!D8/'UTCL-Source Data'!D9 -> 3.9622166 | D27: ='UTCL-Source Data'!E8/'UTCL-Source Data'!E9 -> 3.1887136 | E27: ='UTCL-Source Data'!F8/'UTCL-Source Data'!F9 -> 4.0633803 | F27: ='UTCL-Source Data'!G8/'UTCL-Source Data'!G9 -> 7.4019063 | G27: ='UTCL-Source Data'!H8/'UTCL-Source Data'!H9 -> 11.392231 | H27: ='UTCL-Source Data'!I8/'UTCL-Source Data'!I9 -> 10.60582 | I27: ='UTCL-Source Data'!J8/'UTCL-Source Data'!J9 -> 11.828143 | ... K27: ='UTCL-Source Data'!L8/'UTCL-Source Data'!L9 -> 7.2153374
A29: Growth
A30: Revenue growth | C30: ='UTCL-Source Data'!D3/'UTCL-Source Data'!C3-1 -> 0.22883094 | D30: ='UTCL-Source Data'!E3/'UTCL-Source Data'!D3-1 -> 0.36245657 | E30: ='UTCL-Source Data'!F3/'UTCL-Source Data'!E3-1 -> 0.016250406 | F30: ='UTCL-Source Data'!G3/'UTCL-Source Data'!F3-1 -> 0.062461561 | G30: ='UTCL-Source Data'!H3/'UTCL-Source Data'!G3-1 -> 0.17308049 | H30: ='UTCL-Source Data'!I3/'UTCL-Source Data'!H3-1 -> 0.20871247 | I30: ='UTCL-Source Data'!J3/'UTCL-Source Data'!I3-1 -> 0.12090729 | J30: ='UTCL-Source Data'!K3/'UTCL-Source Data'!J3-1 -> 0.047406069 | K30: ='UTCL-Source Data'!L3/'UTCL-Source Data'!K3-1 -> 0.14291675
A31: Volume growth | C31: ='UTCL-Source Data'!D2/'UTCL-Source Data'!C2-1 -> 0.21403724 | D31: ='UTCL-Source Data'!E2/'UTCL-Source Data'!D2-1 -> 0.36153717 | E31: ='UTCL-Source Data'!F2/'UTCL-Source Data'!E2-1 -> -0.041099282 | F31: ='UTCL-Source Data'!G2/'UTCL-Source Data'!F2-1 -> 0.048928479 | G31: ='UTCL-Source Data'!H2/'UTCL-Source Data'!G2-1 -> 0.083323077 | H31: ='UTCL-Source Data'!I2/'UTCL-Source Data'!H2-1 -> 0.13678709 | I31: ='UTCL-Source Data'!J2/'UTCL-Source Data'!I2-1 -> 0.12742355 | J31: ='UTCL-Source Data'!K2/'UTCL-Source Data'!J2-1 -> 0.11523801 | K31: ='UTCL-Source Data'!L2/'UTCL-Source Data'!K2-1 -> 0.1187505
A32: Realisation growth | C32: =('UTCL-Source Data'!D3/'UTCL-Source Data'!D2)/('UTCL-Source Data'!C3/'UTCL-Source Data'!C2)-1 -> 0.01218554 | D32: =('UTCL-Source Data'!E3/'UTCL-Source Data'!E2)/('UTCL-Source Data'!D3/'UTCL-Source Data'!D2)-1 -> 0.00067527029 | E32: =('UTCL-Source Data'!F3/'UTCL-Source Data'!F2)/('UTCL-Source Data'!E3/'UTCL-Source Data'!E2)-1 -> 0.059807744 | F32: =('UTCL-Source Data'!G3/'UTCL-Source Data'!G2)/('UTCL-Source Data'!F3/'UTCL-Source Data'!F2)-1 -> 0.012901816 | G32: =('UTCL-Source Data'!H3/'UTCL-Source Data'!H2)/('UTCL-Source Data'!G3/'UTCL-Source Data'!G2)-1 -> 0.082853777 | H32: =('UTCL-Source Data'!I3/'UTCL-Source Data'!I2)/('UTCL-Source Data'!H3/'UTCL-Source Data'!H2)-1 -> 0.063270756 | I32: =('UTCL-Source Data'!J3/'UTCL-Source Data'!J2)/('UTCL-Source Data'!I3/'UTCL-Source Data'!I2)-1 -> -0.0057797722 | J32: =('UTCL-Source Data'!K3/'UTCL-Source Data'!K2)/('UTCL-Source Data'!J3/'UTCL-Source Data'!J2)-1 -> -0.060822839 | K32: =('UTCL-Source Data'!L3/'UTCL-Source Data'!L2)/('UTCL-Source Data'!K3/'UTCL-Source Data'!K2)-1 -> 0.021601114
A33: EBITDA growth | C33: ='UTCL-Source Data'!D5/'UTCL-Source Data'!C5-1 -> 0.18394043 | D33: ='UTCL-Source Data'!E5/'UTCL-Source Data'!D5-1 -> 0.20329764 | E33: ='UTCL-Source Data'!F5/'UTCL-Source Data'!E5-1 -> 0.22220653 | F33: ='UTCL-Source Data'!G5/'UTCL-Source Data'!F5-1 -> 0.26733703 | G33: ='UTCL-Source Data'!H5/'UTCL-Source Data'!G5-1 -> -0.0026447788 | H33: ='UTCL-Source Data'!I5/'UTCL-Source Data'!H5-1 -> -0.059436723 | I33: ='UTCL-Source Data'!J5/'UTCL-Source Data'!I5-1 -> 0.22691036 | J33: ='UTCL-Source Data'!K5/'UTCL-Source Data'!J5-1 -> -0.025673534 | K33: ='UTCL-Source Data'!L5/'UTCL-Source Data'!K5-1 -> 0.25561158
A35: The three rows that matter most sit in the Growth block. Over nine years volume compounded at 12.5% while realisation managed 2.0%. UltraTech buys growth with capital rather than earning it through price. The ROIC row confirms it from the other side: 14.5% in FY2021-22 down to 10.8% in FY2025-26, against a cost of capital of about 11%. Note also that FY2018-19 and FY2022-23 are marked Restated in the company's own table, so year on year growth across those boundaries is not strictly like for like.

Sheet UTCL-Assumptions
A1: Assumptions
A3: Tax and market data
A4: Statutory tax rate | B4: 0.25168 | G4: Section 115BAA: 22% plus 10% surcharge plus 4% cess.
A5: Shares outstanding (crore) | B5: 29.468 | G5: Paid up capital Rs 294.68 cr at Rs 10 face value.
A6: Market price per share (30-Mar-2026) | B6: 10745 | G6: NSE close on the last trading day of FY2025-26. 31 March was not a trading day.
A7: Market capitalisation | B7: 316633 | G7: Disclosed in the FY2025-26 report: NSE Rs 3,16,633 cr.
A9: Cost of capital inputs
A10: Indian 10 year G-Sec yield | B10: 0.0685 | G10: SOURCED AND DATE MATCHED. FBIL 10-Year G-Sec Par Yield, week ended 20 March 2026, from the RBI Ratios and Rates release dated 27 March 2026. This is the last weekly print before the 31 March 2026 valuation date, so the risk free rate, the market capitalisation and the balance sheet are all struck on the same window. Nearby prints for context: 6.74% on 13 March, 6.76% on 6 March, 6.71% on 27 February, and 6.65% a year earlier in March 2025.
A11: India sovereign default spread | B11: 0.0187 | G11: Damodaran, Country Default Spreads and Risk Premiums, January 2026. India rated Baa3.
A12: Risk free rate (rupee, default free) | B12: =B10-B11 -> 0.0498 | G12: The G-Sec is not default free because India is rated Baa3. Stripping the default spread is required if the ERP below already contains a country risk premium. Do not do both or neither.
A13: India equity risk premium | B13: 0.0708 | G13: Damodaran, January 2026: mature market 4.23% plus India country risk premium 2.85%. His CDS based alternative is 5.23%.
A14: Unlevered beta, Building Materials | B14: 0.9 | G14: Damodaran Betas by Sector (Global), January 2026: 469 firms, unlevered beta corrected for cash. The cash corrected figure is used because this model adds cash and investments back separately as non operating assets.
A15: Market debt to equity | B15: 0.064681 | G15: Debt of 20,480 over market capitalisation of 316,633.
A16: Levered beta (bottom up) | B16: =B14*(1+(1-B4)*B15) -> 0.94356188 | G16: Hamada relevering at the marginal tax rate.
A17: Pre tax cost of debt | B17: 0.0834 | G17: Derived: FY26 interest of 1,630 over average loan funds of 19,538.
A19: Forecast drivers, FY2026-27 to FY2030-31
A20: Driver | B20: FY27 | C20: FY28 | D20: FY29 | E20: FY30 | F20: FY31
A21: Grey cement capacity (Mn.T) | B21: 186 | C21: 195 | D21: 205 | E21: 213 | F21: 220 | G21: Announced expansion, standalone share. Management guides consolidated capacity of 218 mtpa by FY27 and 240 to 245 mtpa by FY29, of which the 22.8 mtpa FY28 phase (18 North, 4.8 West) is largely brownfield and sits in the standalone entity.
A22: Capacity utilisation | B22: 0.82 | C22: 0.835 | D22: 0.845 | E22: 0.855 | F22: 0.86 | G22: FY26 standalone utilisation is about 81.6%. Management reported roughly 71% consolidated in H1 FY26, a seasonally weak half. Spare capacity means near term volume growth is largely free of new capex.
A23: EBITDA per tonne growth | B23: 0.08 | C23: 0.06 | D23: 0.04 | E23: 0.03 | F23: 0.025 | G23: Management has guided cost savings of about Rs 300 per tonne over two to three years, plus green power rising from 42% to 65%. This path captures roughly two thirds of that. It is DELIBERATELY below the sell side, which models Rs 1,423 per tonne by FY28 against Rs 924 in FY25, a 54% rise in three years.
A24: Depreciation, percent of opening operating assets | B24: 0.050501 | C24: 0.050501 | D24: 0.050501 | E24: 0.050501 | F24: 0.050501 | G24: CONSOLIDATED depreciation and amortisation of 4,644.46 over the opening consolidated operating asset base of 91,968.32, which includes intangibles. The charge and the base must cover the same assets.
A25: Subsidiary revenue growth | B25: 0.06 | C25: 0.055 | D25: 0.05 | E25: 0.045 | F25: 0.04 | G25: The subsidiary block is principally India Cements, which management is integrating. Growth is assumed slightly below the standalone business.
A26: Subsidiary EBITDA margin | B26: 0.25 | C26: 0.252 | D26: 0.254 | E26: 0.256 | F26: 0.258 | G26: Base year 24.9%. Held broadly flat with modest improvement as integration completes.
A27: Capital expenditure | B27: 9500 | C27: 9500 | D27: 9000 | E27: 8500 | F27: 8500 | G27: Management has guided about Rs 10,000 crore a year consolidated for the next two years. This is the standalone share, tapering as the current expansion phase completes. Capex is now an explicit input rather than derived from capital intensity, because scaling assets to revenue penalised the company for capacity it has already built and is only 82% utilising.
A28: Net working capital, percent of revenue | B28: -0.0374 | C28: -0.0374 | D28: -0.0374 | E28: -0.0374 | F28: -0.0374 | G28: Negative NWC is structural for UltraTech and has been so for nine of ten years.
A30: Terminal and capital structure
A31: Long run real GDP growth | B31: 0.065 | G31: RBI and Economic Survey long run figure. Owned assumption, sensitize it.
A32: Long run inflation | B32: 0.04 | G32: RBI's CPI target of 4% (band 2% to 6%).
A33: Nominal GDP growth (multiplicative) | B33: =(1+B31)*(1+B32)-1 -> 0.1076 | G33: Built as (1+real)(1+inflation)-1, NOT real plus inflation. 6.5% and 4% give 10.76%, not 10.5%.
A34: Terminal growth as a fraction of nominal GDP | B34: 0.65 | G34: 65.0% of nominal GDP, giving 6.99%. RAISED from 46.5% to reflect India's infrastructure runway, which is a genuine medium term demand driver. The HARD CONSTRAINT is that terminal growth can never exceed nominal GDP of 10.76%: a company growing faster than the economy forever eventually becomes larger than the economy. A peer multiple of 19.4x implies 10.99%, which breaches that constraint and is the basis on which this model rejects the peer multiple. Adopting 10.99% ourselves would contradict our own central argument. The same fraction is used for both companies so the two are treated consistently.
A35: Terminal growth rate | B35: =B33*B34 -> 0.06994 | G35: Derived, not typed. Change the fraction above, not this cell.
A36: Target debt to enterprise value | B36: 0.060751 | G36: Current market value leverage: debt of 20,480 over 20,480 plus market cap. Constant rebalancing is assumed, which is what makes the five methods agree.
A38: Non operating assets at 31 March 2026
A39: Liquid investments | B39: 1384.35 | G39: Added to operating enterprise value.
A40: India Cements: shares held (crore) | B40: 23.241683 | G40: From the non-current investments note: 23,24,16,830 shares, a 74.99% holding.
A41: India Cements: carrying value | B41: 0 | G41: Book value in the same note. Works out to Rs 385.95 per share.
A42: India Cements: market price per share | G42: LEAVE BLANK until sourced from NSE. India Cements is LISTED, so asset consistency requires this stake at market value, not book. Blank means the model falls back to carrying value.
A43: India Cements: value used | B43: =IF(B42="",B41,B40*B42) -> 0 | G43: Market value in Rs crore is shares in crore times price in rupees.
A44: Other investments at book | B44: 6739.51 | G44: Total investments in subsidiaries, associates and others of 12,541 less the India Cements carrying value.
A45: Investments in subsidiaries and others | B45: =B43+B44 -> 6739.51 | G45: Feeds the equity bridge in all five valuation methods.
...

Sheet UTCL-P&L
A1: Line item | B1: Unit | C1: FY2026-27 | D1: FY2027-28 | E1: FY2028-29 | F1: FY2029-30 | G1: FY2030-31
A2: Grey cement capacity | B2: Mn.T | C2: ='UTCL-Assumptions'!B21 -> 186 | D2: ='UTCL-Assumptions'!C21 -> 195 | E2: ='UTCL-Assumptions'!D21 -> 205 | F2: ='UTCL-Assumptions'!E21 -> 213 | G2: ='UTCL-Assumptions'!F21 -> 220
A3: Capacity utilisation | B3: % | C3: ='UTCL-Assumptions'!B22 -> 0.82 | D3: ='UTCL-Assumptions'!C22 -> 0.835 | E3: ='UTCL-Assumptions'!D22 -> 0.845 | F3: ='UTCL-Assumptions'!E22 -> 0.855 | G3: ='UTCL-Assumptions'!F22 -> 0.86
A4: Grey cement sales volume | B4: Mn.T | C4: =C2*C3 -> 152.52 | D4: =D2*D3 -> 162.825 | E4: =E2*E3 -> 173.225 | F4: =F2*F3 -> 182.115 | G4: =G2*G3 -> 189.2
A5: EBITDA per tonne | B5: Rs/t | C5: ='UTCL-Assumptions'!$B$52*(1+'UTCL-Assumptions'!B23) -> 1184.6628 | D5: =C5*(1+'UTCL-Assumptions'!C23) -> 1255.7426 | E5: =D5*(1+'UTCL-Assumptions'!D23) -> 1305.9723 | F5: =E5*(1+'UTCL-Assumptions'!E23) -> 1345.1514 | G5: =F5*(1+'UTCL-Assumptions'!F23) -> 1378.7802
